<?xml version="1.0" ?>
<mujoco>
  <default>
    <default class="xhand_right">
      <default class="xhand_right-motor">
        <joint/>
        <motor/>
      </default>
      <default class="xhand_right-visual">
        <geom material="xhand_right-visualgeom" contype="0" conaffinity="0" group="2"/>
      </default>
      <default class="xhand_right-collision">
        <geom material="xhand_right-collision_material" condim="3" contype="0" conaffinity="1" priority="1" group="1" solref="0.005 1" friction="1 0.01 0.01"/>
        <equality solimp="0.99 0.999 1e-05" solref="0.005 1"/>
      </default>
    </default>
  </default>
  <compiler angle="radian"/>
  <asset>
    <material name="xhand_right-RAL_9005_Jet_Black" rgba="0.055 0.055 0.063 1"/>
    <material name="xhand_right-RAL_9003_Signal_White" rgba="0.941 0.941 0.941 1"/>
    <material name="xhand_right-default_material" rgba="0.7 0.7 0.7 1"/>
    <material name="xhand_right-collision_material" rgba="1.0 0.28 0.1 0.9"/>
    <mesh name="xhand_right-right_hand_link.STL" file="./right_hand_link.STL"/>
    <mesh name="xhand_right-right_hand_ee_link.STL" file="./right_hand_ee_link.STL"/>
    <mesh name="xhand_right-right_hand_back_link.STL" file="./right_hand_back_link.STL"/>
    <mesh name="xhand_right-right_hand_thumb_bend_link.STL" file="./right_hand_thumb_bend_link.STL"/>
    <mesh name="xhand_right-right_hand_thumb_rota_link1.STL" file="./right_hand_thumb_rota_link1.STL"/>
    <mesh name="xhand_right-right_hand_thumb_rotaback_link1.STL" file="./right_hand_thumb_rotaback_link1.STL"/>
    <mesh name="xhand_right-right_hand_thumb_rota_link2.STL" file="./right_hand_thumb_rota_link2.STL"/>
    <mesh name="xhand_right-right_hand_thumb_rotaback_link2.STL" file="./right_hand_thumb_rotaback_link2.STL"/>
    <mesh name="xhand_right-right_hand_thumb_rota_tip.STL" file="./right_hand_thumb_rota_tip.STL"/>
    <mesh name="xhand_right-right_hand_index_bend_link.STL" file="./right_hand_index_bend_link.STL"/>
    <mesh name="xhand_right-right_hand_index_rota_link1.STL" file="./right_hand_index_rota_link1.STL"/>
    <mesh name="xhand_right-right_hand_index_rotaback_link1.STL" file="./right_hand_index_rotaback_link1.STL"/>
    <mesh name="xhand_right-right_hand_index_rota_link2.STL" file="./right_hand_index_rota_link2.STL"/>
    <mesh name="xhand_right-right_hand_index_rotaback_link2.STL" file="./right_hand_index_rotaback_link2.STL"/>
    <mesh name="xhand_right-right_hand_index_rota_tip.STL" file="./right_hand_index_rota_tip.STL"/>
    <mesh name="xhand_right-right_hand_mid_link1.STL" file="./right_hand_mid_link1.STL"/>
    <mesh name="xhand_right-right_hand_midback_link1.STL" file="./right_hand_midback_link1.STL"/>
    <mesh name="xhand_right-right_hand_mid_link2.STL" file="./right_hand_mid_link2.STL"/>
    <mesh name="xhand_right-right_hand_midback_link2.STL" file="./right_hand_midback_link2.STL"/>
    <mesh name="xhand_right-right_hand_mid_tip.STL" file="./right_hand_mid_tip.STL"/>
    <mesh name="xhand_right-right_hand_ring_link1.STL" file="./right_hand_ring_link1.STL"/>
    <mesh name="xhand_right-right_hand_ringback_link1.STL" file="./right_hand_ringback_link1.STL"/>
    <mesh name="xhand_right-right_hand_ring_link2.STL" file="./right_hand_ring_link2.STL"/>
    <mesh name="xhand_right-right_hand_ringback_link2.STL" file="./right_hand_ringback_link2.STL"/>
    <mesh name="xhand_right-right_hand_ring_tip.STL" file="./right_hand_ring_tip.STL"/>
    <mesh name="xhand_right-right_hand_pinky_link1.STL" file="./right_hand_pinky_link1.STL"/>
    <mesh name="xhand_right-right_hand_pinkyback_link1.STL" file="./right_hand_pinkyback_link1.STL"/>
    <mesh name="xhand_right-right_hand_pinky_link2.STL" file="./right_hand_pinky_link2.STL"/>
    <mesh name="xhand_right-right_hand_pinkyback_link2.STL" file="./right_hand_pinkyback_link2.STL"/>
    <mesh name="xhand_right-right_hand_pinky_tip.STL" file="./right_hand_pinky_tip.STL"/>
  </asset>
  <worldbody>
    <body name="xhand_right" childclass="xhand_right" pos="0 0 0.20624829" quat="0.7071 0.7071 0 0">
      <joint name="xhand_right-floating_base"/>
      <geom name="xhand_right-right_hand_link_collision" pos="0 0 0" quat="1.0 0.0 0.0 0.0" type="mesh" mesh="xhand_right-right_hand_link.STL" class="xhand_right-collision"/>
      <geom name="xhand_right-right_hand_link_visual" pos="0 0 0" quat="1.0 0.0 0.0 0.0" material="xhand_right-RAL_9005_Jet_Black" type="mesh" mesh="xhand_right-right_hand_link.STL" class="xhand_right-visual"/>
      <body name="xhand_right-right_hand_ee_link" pos="0 0 -0.065" quat="1.0 0.0 0.0 0.0">
        <inertial pos="2.48510213245214E-19 -8.08284973285247E-18 0" quat="1.0 0.0 0.0 0.0" mass="0.00000565" diaginertia="1e-11 1e-11 1e-11"/>
        <geom name="xhand_right-right_hand_ee_link_collision" pos="0 0 0" quat="1.0 0.0 0.0 0.0" type="mesh" mesh="xhand_right-right_hand_ee_link.STL" class="xhand_right-collision"/>
        <geom name="xhand_right-right_hand_ee_link_visual" pos="0 0 0" quat="1.0 0.0 0.0 0.0" material="xhand_right-RAL_9005_Jet_Black" type="mesh" mesh="xhand_right-right_hand_ee_link.STL" class="xhand_right-visual"/>
      </body>
      <body name="xhand_right-right_hand_back_link" pos="0 0 -0.065" quat="1.0 0.0 0.0 0.0">
        <inertial pos="-0.00149243508011096 -0.0140081556490721 0.000647100828228067" quat="1.0 0.0 0.0 0.0" mass="0.00000020" diaginertia="1e-11 1e-11 1e-11"/>
        <geom name="xhand_right-right_hand_back_link_collision" pos="0 0 0" quat="1.0 0.0 0.0 0.0" type="mesh" mesh="xhand_right-right_hand_back_link.STL" class="xhand_right-collision"/>
        <geom name="xhand_right-right_hand_back_link_visual" pos="0 0 0" quat="1.0 0.0 0.0 0.0" material="xhand_right-RAL_9003_Signal_White" type="mesh" mesh="xhand_right-right_hand_back_link.STL" class="xhand_right-visual"/>
      </body>
      <body name="xhand_right-right_hand_thumb_bend_link" pos="0.0228 0.0095 -0.0305" quat="1.0 0.0 0.0 0.0">
        <joint name="xhand_right-right_hand_thumb_bend_joint" type="hinge" ref="0.0" class="xhand_right-motor" range="0 1.832" axis="0 0 1"/>
        <inertial pos="0.0144358799903648 -0.00116534489100676 -5.40665183231849E-05" quat="1.0 0.0 0.0 0.0" mass="0.01174632" diaginertia="6.2e-07 1.6e-06 1.62e-06"/>
        <geom name="xhand_right-right_hand_thumb_bend_link_collision" pos="0 0 0" quat="1.0 0.0 0.0 0.0" type="mesh" mesh="xhand_right-right_hand_thumb_bend_link.STL" class="xhand_right-collision"/>
        <geom name="xhand_right-right_hand_thumb_bend_link_visual" pos="0 0 0" quat="1.0 0.0 0.0 0.0" material="xhand_right-RAL_9005_Jet_Black" type="mesh" mesh="xhand_right-right_hand_thumb_bend_link.STL" class="xhand_right-visual"/>
        <body name="xhand_right-right_hand_thumb_rota_link1" pos="0.028599 0.0083177 0.00178" quat="0.991239538700108 0.1304994696550749 0.0026560308583164923 0.020174509595553045">
          <joint name="xhand_right-right_hand_thumb_rota_joint1" type="hinge" ref="0.0" class="xhand_right-motor" range="-0.698 1.745" axis="0 1 0"/>
          <inertial pos="0.0287681482733488 -0.00036176529547633 -0.00133929681686046" quat="1.0 0.0 0.0 0.0" mass="0.13266642" diaginertia="1.699e-05 3.679e-05 4.374e-05"/>
          <geom name="xhand_right-right_hand_thumb_rota_link1_collision" pos="0 0 0" quat="1.0 0.0 0.0 0.0" type="mesh" mesh="xhand_right-right_hand_thumb_rota_link1.STL" class="xhand_right-collision"/>
          <geom name="xhand_right-right_hand_thumb_rota_link1_visual" pos="0 0 0" quat="1.0 0.0 0.0 0.0" material="xhand_right-RAL_9005_Jet_Black" type="mesh" mesh="xhand_right-right_hand_thumb_rota_link1.STL" class="xhand_right-visual"/>
          <body name="xhand_right-right_hand_thumb_rotaback_link1" pos="0.0553000000000007 0 0" quat="1.0 0.0 0.0 0.0">
            <inertial pos="-0.0296289408411864 0.0014334239435258 0.00759117850867843" quat="1.0 0.0 0.0 0.0" mass="0.00000006" diaginertia="1e-11 1e-11 1e-11"/>
            <geom name="xhand_right-right_hand_thumb_rotaback_link1_collision" pos="0 0 0" quat="1.0 0.0 0.0 0.0" type="mesh" mesh="xhand_right-right_hand_thumb_rotaback_link1.STL" class="xhand_right-collision"/>
            <geom name="xhand_right-right_hand_thumb_rotaback_link1_visual" pos="0 0 0" quat="1.0 0.0 0.0 0.0" material="xhand_right-RAL_9003_Signal_White" type="mesh" mesh="xhand_right-right_hand_thumb_rotaback_link1.STL" class="xhand_right-visual"/>
          </body>
          <body name="xhand_right-right_hand_thumb_rota_link2" pos="0.0553 0 0" quat="1.0 0.0 0.0 0.0">
            <joint name="xhand_right-right_hand_thumb_rota_joint2" type="hinge" ref="0.0" class="xhand_right-motor" range="0 1.745" axis="0 1 0"/>
            <inertial pos="0.0225340009927979 -0.000881600697645881 -0.000614548321208525" quat="1.0 0.0 0.0 0.0" mass="0.04336091" diaginertia="3.88e-06 9.02e-06 1.046e-05"/>
            <geom name="xhand_right-right_hand_thumb_rota_link2_collision" pos="0 0 0" quat="1.0 0.0 0.0 0.0" type="mesh" mesh="xhand_right-right_hand_thumb_rota_link2.STL" class="xhand_right-collision"/>
            <geom name="xhand_right-right_hand_thumb_rota_link2_visual" pos="0 0 0" quat="1.0 0.0 0.0 0.0" material="xhand_right-RAL_9005_Jet_Black" type="mesh" mesh="xhand_right-right_hand_thumb_rota_link2.STL" class="xhand_right-visual"/>
            <body name="xhand_right-right_hand_thumb_rotaback_link2" pos="0.0502276499414862 0 0" quat="1.0 0.0 0.0 0.0">
              <inertial pos="-0.0258393463672562 -0.000532639688528967 0.00924631171368789" quat="1.0 0.0 0.0 0.0" mass="0.00000004" diaginertia="1e-11 1e-11 1e-11"/>
              <geom name="xhand_right-right_hand_thumb_rotaback_link2_collision" pos="0 0 0" quat="1.0 0.0 0.0 0.0" type="mesh" mesh="xhand_right-right_hand_thumb_rotaback_link2.STL" class="xhand_right-collision"/>
              <geom name="xhand_right-right_hand_thumb_rotaback_link2_visual" pos="0 0 0" quat="1.0 0.0 0.0 0.0" material="xhand_right-RAL_9003_Signal_White" type="mesh" mesh="xhand_right-right_hand_thumb_rotaback_link2.STL" class="xhand_right-visual"/>
            </body>
            <body name="xhand_right-right_hand_thumb_rota_tip" pos="0.0502276499414862 0 0" quat="1.0 0.0 0.0 0.0">
              <inertial pos="8.32667268468867E-17 -8.67361737988404E-19 -5.55111512312578E-17" quat="1.0 0.0 0.0 0.0" mass="0.00000565" diaginertia="1e-11 1e-11 1e-11"/>
              <geom name="xhand_right-right_hand_thumb_rota_tip_collision" pos="0 0 0" quat="1.0 0.0 0.0 0.0" type="mesh" mesh="xhand_right-right_hand_thumb_rota_tip.STL" class="xhand_right-collision"/>
              <geom name="xhand_right-right_hand_thumb_rota_tip_visual" pos="0 0 0" quat="1.0 0.0 0.0 0.0" material="xhand_right-RAL_9005_Jet_Black" type="mesh" mesh="xhand_right-right_hand_thumb_rota_tip.STL" class="xhand_right-visual"/>
            </body>
          </body>
        </body>
      </body>
      <body name="xhand_right-right_hand_index_bend_link" pos="0.0265 0.0065 -0.0899" quat="1.0 0.0 0.0 0.0">
        <joint name="xhand_right-right_hand_index_bend_joint" type="hinge" ref="0.0" class="xhand_right-motor" range="-0.174 0.174" axis="0 -1 0"/>
        <inertial pos="0.000118997558760787 -0.000715851164577269 -0.0111903014853532" quat="1.0 0.0 0.0 0.0" mass="0.06910833" diaginertia="1.74e-05 1.677e-05 3.45e-06"/>
        <geom name="xhand_right-right_hand_index_bend_link_collision" pos="0 0 0" quat="1.0 0.0 0.0 0.0" type="mesh" mesh="xhand_right-right_hand_index_bend_link.STL" class="xhand_right-collision"/>
        <geom name="xhand_right-right_hand_index_bend_link_visual" pos="0 0 0" quat="1.0 0.0 0.0 0.0" material="xhand_right-RAL_9005_Jet_Black" type="mesh" mesh="xhand_right-right_hand_index_bend_link.STL" class="xhand_right-visual"/>
        <body name="xhand_right-right_hand_index_rota_link1" pos="0 0 -0.0178" quat="1.0 0.0 0.0 0.0">
          <joint name="xhand_right-right_hand_index_joint1" type="hinge" ref="0.0" class="xhand_right-motor" range="0 1.919" axis="1 0 0"/>
          <inertial pos="0.000133008106573459 0.000632930512954057 -0.0355868719939061" quat="1.0 0.0 0.0 0.0" mass="0.06298297" diaginertia="1.738e-05 1.686e-05 3.2e-06"/>
          <geom name="xhand_right-right_hand_index_rota_link1_collision" pos="0 0 0" quat="1.0 0.0 0.0 0.0" type="mesh" mesh="xhand_right-right_hand_index_rota_link1.STL" class="xhand_right-collision"/>
          <geom name="xhand_right-right_hand_index_rota_link1_visual" pos="0 0 0" quat="1.0 0.0 0.0 0.0" material="xhand_right-RAL_9005_Jet_Black" type="mesh" mesh="xhand_right-right_hand_index_rota_link1.STL" class="xhand_right-visual"/>
          <body name="xhand_right-right_hand_index_rotaback_link1" pos="0 0 -0.0557999999999955" quat="1.0 0.0 0.0 0.0">
            <inertial pos="-0.000148035114615745 -0.0115948040516035 0.0241234077593065" quat="1.0 0.0 0.0 0.0" mass="0.00000002" diaginertia="1e-11 1e-11 1e-11"/>
            <geom name="xhand_right-right_hand_index_rotaback_link1_collision" pos="0 0 0" quat="1.0 0.0 0.0 0.0" type="mesh" mesh="xhand_right-right_hand_index_rotaback_link1.STL" class="xhand_right-collision"/>
            <geom name="xhand_right-right_hand_index_rotaback_link1_visual" pos="0 0 0" quat="1.0 0.0 0.0 0.0" material="xhand_right-RAL_9003_Signal_White" type="mesh" mesh="xhand_right-right_hand_index_rotaback_link1.STL" class="xhand_right-visual"/>
          </body>
          <body name="xhand_right-right_hand_index_rota_link2" pos="0 0 -0.0558" quat="1.0 0.0 0.0 0.0">
            <joint name="xhand_right-right_hand_index_joint2" type="hinge" ref="0.0" class="xhand_right-motor" range="0 1.919" axis="1 0 0"/>
            <inertial pos="-0.000248361661985549 0.00119905190206764 -0.0213789854478675" quat="1.0 0.0 0.0 0.0" mass="0.01588724" diaginertia="2.77e-06 2.83e-06 8.5e-07"/>
            <geom name="xhand_right-right_hand_index_rota_link2_collision" pos="0 0 0" quat="1.0 0.0 0.0 0.0" type="mesh" mesh="xhand_right-right_hand_index_rota_link2.STL" class="xhand_right-collision"/>
            <geom name="xhand_right-right_hand_index_rota_link2_visual" pos="0 0 0" quat="1.0 0.0 0.0 0.0" material="xhand_right-RAL_9005_Jet_Black" type="mesh" mesh="xhand_right-right_hand_index_rota_link2.STL" class="xhand_right-visual"/>
            <body name="xhand_right-right_hand_index_rotaback_link2" pos="0 0 -0.0422482924089416" quat="1.0 0.0 0.0 0.0">
              <inertial pos="0.00015795043863779 -0.00758843721876498 0.017665521085611" quat="1.0 0.0 0.0 0.0" mass="0.00000001" diaginertia="1e-11 1e-11 1e-11"/>
              <geom name="xhand_right-right_hand_index_rotaback_link2_collision" pos="0 0 0" quat="1.0 0.0 0.0 0.0" type="mesh" mesh="xhand_right-right_hand_index_rotaback_link2.STL" class="xhand_right-collision"/>
              <geom name="xhand_right-right_hand_index_rotaback_link2_visual" pos="0 0 0" quat="1.0 0.0 0.0 0.0" material="xhand_right-RAL_9003_Signal_White" type="mesh" mesh="xhand_right-right_hand_index_rotaback_link2.STL" class="xhand_right-visual"/>
            </body>
            <body name="xhand_right-right_hand_index_rota_tip" pos="0 0 -0.0422482924089416" quat="1.0 0.0 0.0 0.0">
              <inertial pos="3.70675712346724E-14 8.65627014512427E-16 -8.32667268468867E-16" quat="1.0 0.0 0.0 0.0" mass="0.00000565" diaginertia="1e-11 1e-11 1e-11"/>
              <geom name="xhand_right-right_hand_index_rota_tip_collision" pos="0 0 0" quat="1.0 0.0 0.0 0.0" type="mesh" mesh="xhand_right-right_hand_index_rota_tip.STL" class="xhand_right-collision"/>
              <geom name="xhand_right-right_hand_index_rota_tip_visual" pos="0 0 0" quat="1.0 0.0 0.0 0.0" material="xhand_right-RAL_9005_Jet_Black" type="mesh" mesh="xhand_right-right_hand_index_rota_tip.STL" class="xhand_right-visual"/>
            </body>
          </body>
        </body>
      </body>
      <body name="xhand_right-right_hand_mid_link1" pos="0.004 0.0065 -0.1082" quat="1.0 0.0 0.0 0.0">
        <joint name="xhand_right-right_hand_mid_joint1" type="hinge" ref="0.0" class="xhand_right-motor" range="0 1.919" axis="1 0 0"/>
        <inertial pos="3.58049083993136E-05 0.000530417592106078 -0.0332784671157236" quat="1.0 0.0 0.0 0.0" mass="0.06298297" diaginertia="1.738e-05 1.686e-05 3.2e-06"/>
        <geom name="xhand_right-right_hand_mid_link1_collision" pos="0 0 0" quat="1.0 0.0 0.0 0.0" type="mesh" mesh="xhand_right-right_hand_mid_link1.STL" class="xhand_right-collision"/>
        <geom name="xhand_right-right_hand_mid_link1_visual" pos="0 0 0" quat="1.0 0.0 0.0 0.0" material="xhand_right-RAL_9005_Jet_Black" type="mesh" mesh="xhand_right-right_hand_mid_link1.STL" class="xhand_right-visual"/>
        <body name="xhand_right-right_hand_midback_link1" pos="0 0 -0.0558" quat="1.0 0.0 0.0 0.0">
          <inertial pos="-0.000148035028410428 -0.0115948040189855 0.0241234086343709" quat="1.0 0.0 0.0 0.0" mass="0.00000002" diaginertia="1e-11 1e-11 1e-11"/>
          <geom name="xhand_right-right_hand_midback_link1_collision" pos="0 0 0" quat="1.0 0.0 0.0 0.0" type="mesh" mesh="xhand_right-right_hand_midback_link1.STL" class="xhand_right-collision"/>
          <geom name="xhand_right-right_hand_midback_link1_visual" pos="0 0 0" quat="1.0 0.0 0.0 0.0" material="xhand_right-RAL_9003_Signal_White" type="mesh" mesh="xhand_right-right_hand_midback_link1.STL" class="xhand_right-visual"/>
        </body>
        <body name="xhand_right-right_hand_mid_link2" pos="0 0 -0.0558" quat="1.0 0.0 0.0 0.0">
          <joint name="xhand_right-right_hand_mid_joint2" type="hinge" ref="0.0" class="xhand_right-motor" range="0 1.919" axis="1 0 0"/>
          <inertial pos="-0.000248364601983051 0.00119905076177324 -0.0213789908421273" quat="1.0 0.0 0.0 0.0" mass="0.01624108" diaginertia="2.81e-06 2.87e-06 8.6e-07"/>
          <geom name="xhand_right-right_hand_mid_link2_collision" pos="0 0 0" quat="1.0 0.0 0.0 0.0" type="mesh" mesh="xhand_right-right_hand_mid_link2.STL" class="xhand_right-collision"/>
          <geom name="xhand_right-right_hand_mid_link2_visual" pos="0 0 0" quat="1.0 0.0 0.0 0.0" material="xhand_right-RAL_9005_Jet_Black" type="mesh" mesh="xhand_right-right_hand_mid_link2.STL" class="xhand_right-visual"/>
          <body name="xhand_right-right_hand_midback_link2" pos="0 0 -0.042248" quat="1.0 0.0 0.0 0.0">
            <inertial pos="0.000157950438652398 -0.00758843721877396 0.0176655210856773" quat="1.0 0.0 0.0 0.0" mass="0.00000001" diaginertia="1e-11 1e-11 1e-11"/>
            <geom name="xhand_right-right_hand_midback_link2_collision" pos="0 0 0" quat="1.0 0.0 0.0 0.0" type="mesh" mesh="xhand_right-right_hand_midback_link2.STL" class="xhand_right-collision"/>
            <geom name="xhand_right-right_hand_midback_link2_visual" pos="0 0 0" quat="1.0 0.0 0.0 0.0" material="xhand_right-RAL_9003_Signal_White" type="mesh" mesh="xhand_right-right_hand_midback_link2.STL" class="xhand_right-visual"/>
          </body>
          <body name="xhand_right-right_hand_mid_tip" pos="0 0 -0.0422482924089417" quat="1.0 0.0 0.0 0.0">
            <inertial pos="5.97126514900737E-14 5.86336534880161E-16 -8.32667268468867E-16" quat="1.0 0.0 0.0 0.0" mass="0.00000565" diaginertia="1e-11 1e-11 1e-11"/>
            <geom name="xhand_right-right_hand_mid_tip_collision" pos="0 0 0" quat="1.0 0.0 0.0 0.0" type="mesh" mesh="xhand_right-right_hand_mid_tip.STL" class="xhand_right-collision"/>
            <geom name="xhand_right-right_hand_mid_tip_visual" pos="0 0 0" quat="1.0 0.0 0.0 0.0" material="xhand_right-RAL_9005_Jet_Black" type="mesh" mesh="xhand_right-right_hand_mid_tip.STL" class="xhand_right-visual"/>
          </body>
        </body>
      </body>
      <body name="xhand_right-right_hand_ring_link1" pos="-0.016 0.0065 -0.1052" quat="1.0 0.0 0.0 0.0">
        <joint name="xhand_right-right_hand_ring_joint1" type="hinge" ref="0.0" class="xhand_right-motor" range="0 1.919" axis="1 0 0"/>
        <inertial pos="3.58049083615322E-05 0.000530417592105594 -0.0332784671157224" quat="1.0 0.0 0.0 0.0" mass="0.06298297" diaginertia="1.738e-05 1.686e-05 3.2e-06"/>
        <geom name="xhand_right-right_hand_ring_link1_collision" pos="0 0 0" quat="1.0 0.0 0.0 0.0" type="mesh" mesh="xhand_right-right_hand_ring_link1.STL" class="xhand_right-collision"/>
        <geom name="xhand_right-right_hand_ring_link1_visual" pos="0 0 0" quat="1.0 0.0 0.0 0.0" material="xhand_right-RAL_9005_Jet_Black" type="mesh" mesh="xhand_right-right_hand_ring_link1.STL" class="xhand_right-visual"/>
        <body name="xhand_right-right_hand_ringback_link1" pos="0 0 -0.0558000000000002" quat="1.0 0.0 0.0 0.0">
          <inertial pos="-0.000148033469798928 -0.0115948018402145 0.0241234223266379" quat="1.0 0.0 0.0 0.0" mass="0.00000002" diaginertia="1e-11 1e-11 1e-11"/>
          <geom name="xhand_right-right_hand_ringback_link1_collision" pos="0 0 0" quat="1.0 0.0 0.0 0.0" type="mesh" mesh="xhand_right-right_hand_ringback_link1.STL" class="xhand_right-collision"/>
          <geom name="xhand_right-right_hand_ringback_link1_visual" pos="0 0 0" quat="1.0 0.0 0.0 0.0" material="xhand_right-RAL_9003_Signal_White" type="mesh" mesh="xhand_right-right_hand_ringback_link1.STL" class="xhand_right-visual"/>
        </body>
        <body name="xhand_right-right_hand_ring_link2" pos="0 0 -0.0558" quat="1.0 0.0 0.0 0.0">
          <joint name="xhand_right-right_hand_ring_joint2" type="hinge" ref="0.0" class="xhand_right-motor" range="0 1.919" axis="1 0 0"/>
          <inertial pos="-0.000248364602035429 0.00119905076177346 -0.0213789908421257" quat="1.0 0.0 0.0 0.0" mass="0.01624108" diaginertia="2.81e-06 2.87e-06 8.6e-07"/>
          <geom name="xhand_right-right_hand_ring_link2_collision" pos="0 0 0" quat="1.0 0.0 0.0 0.0" type="mesh" mesh="xhand_right-right_hand_ring_link2.STL" class="xhand_right-collision"/>
          <geom name="xhand_right-right_hand_ring_link2_visual" pos="0 0 0" quat="1.0 0.0 0.0 0.0" material="xhand_right-RAL_9005_Jet_Black" type="mesh" mesh="xhand_right-right_hand_ring_link2.STL" class="xhand_right-visual"/>
          <body name="xhand_right-right_hand_ringback_link2" pos="0 0 -0.0422482924089403" quat="1.0 0.0 0.0 0.0">
            <inertial pos="0.000157950438638532 -0.00758843721878611 0.0176655210858899" quat="1.0 0.0 0.0 0.0" mass="0.00000001" diaginertia="1e-11 1e-11 1e-11"/>
            <geom name="xhand_right-right_hand_ringback_link2_collision" pos="0 0 0" quat="1.0 0.0 0.0 0.0" type="mesh" mesh="xhand_right-right_hand_ringback_link2.STL" class="xhand_right-collision"/>
            <geom name="xhand_right-right_hand_ringback_link2_visual" pos="0 0 0" quat="1.0 0.0 0.0 0.0" material="xhand_right-RAL_9003_Signal_White" type="mesh" mesh="xhand_right-right_hand_ringback_link2.STL" class="xhand_right-visual"/>
          </body>
          <body name="xhand_right-right_hand_ring_tip" pos="0 0 -0.0422482924089403" quat="1.0 0.0 0.0 0.0">
            <inertial pos="1.22818422099158E-15 1.69135538907739E-16 0" quat="1.0 0.0 0.0 0.0" mass="0.00000565" diaginertia="1e-11 1e-11 1e-11"/>
            <geom name="xhand_right-right_hand_ring_tip_collision" pos="0 0 0" quat="1.0 0.0 0.0 0.0" type="mesh" mesh="xhand_right-right_hand_ring_tip.STL" class="xhand_right-collision"/>
            <geom name="xhand_right-right_hand_ring_tip_visual" pos="0 0 0" quat="1.0 0.0 0.0 0.0" material="xhand_right-RAL_9005_Jet_Black" type="mesh" mesh="xhand_right-right_hand_ring_tip.STL" class="xhand_right-visual"/>
          </body>
        </body>
      </body>
      <body name="xhand_right-right_hand_pinky_link1" pos="-0.036 0.0065 -0.1022" quat="1.0 0.0 0.0 0.0">
        <joint name="xhand_right-right_hand_pinky_joint1" type="hinge" ref="0.0" class="xhand_right-motor" range="0 1.919" axis="1 0 0"/>
        <inertial pos="3.58049083611298E-05 0.000530417592105422 -0.0332784671157224" quat="1.0 0.0 0.0 0.0" mass="0.06298297" diaginertia="1.738e-05 1.686e-05 3.2e-06"/>
        <geom name="xhand_right-right_hand_pinky_link1_collision" pos="0 0 0" quat="1.0 0.0 0.0 0.0" type="mesh" mesh="xhand_right-right_hand_pinky_link1.STL" class="xhand_right-collision"/>
        <geom name="xhand_right-right_hand_pinky_link1_visual" pos="0 0 0" quat="1.0 0.0 0.0 0.0" material="xhand_right-RAL_9005_Jet_Black" type="mesh" mesh="xhand_right-right_hand_pinky_link1.STL" class="xhand_right-visual"/>
        <body name="xhand_right-right_hand_pinkyback_link1" pos="0 0 -0.0558000000000001" quat="1.0 0.0 0.0 0.0">
          <inertial pos="-0.000148034891232163 -0.0115948044185708 0.0241234089219646" quat="1.0 0.0 0.0 0.0" mass="0.00000002" diaginertia="1e-11 1e-11 1e-11"/>
          <geom name="xhand_right-right_hand_pinkyback_link1_collision" pos="0 0 0" quat="1.0 0.0 0.0 0.0" type="mesh" mesh="xhand_right-right_hand_pinkyback_link1.STL" class="xhand_right-collision"/>
          <geom name="xhand_right-right_hand_pinkyback_link1_visual" pos="0 0 0" quat="1.0 0.0 0.0 0.0" material="xhand_right-RAL_9003_Signal_White" type="mesh" mesh="xhand_right-right_hand_pinkyback_link1.STL" class="xhand_right-visual"/>
        </body>
        <body name="xhand_right-right_hand_pinky_link2" pos="0 0 -0.0558" quat="1.0 0.0 0.0 0.0">
          <joint name="xhand_right-right_hand_pinky_joint2" type="hinge" ref="0.0" class="xhand_right-motor" range="0 1.919" axis="1 0 0"/>
          <inertial pos="-0.000248361662015334 0.0011990519020671 -0.0213789854478658" quat="1.0 0.0 0.0 0.0" mass="0.01624108" diaginertia="2.81e-06 2.87e-06 8.6e-07"/>
          <geom name="xhand_right-right_hand_pinky_link2_collision" pos="0 0 0" quat="1.0 0.0 0.0 0.0" type="mesh" mesh="xhand_right-right_hand_pinky_link2.STL" class="xhand_right-collision"/>
          <geom name="xhand_right-right_hand_pinky_link2_visual" pos="0 0 0" quat="1.0 0.0 0.0 0.0" material="xhand_right-RAL_9005_Jet_Black" type="mesh" mesh="xhand_right-right_hand_pinky_link2.STL" class="xhand_right-visual"/>
          <body name="xhand_right-right_hand_pinkyback_link2" pos="0 0 -0.0422482924089404" quat="1.0 0.0 0.0 0.0">
            <inertial pos="0.00015795043861809 -0.00758843721877113 0.0176655210856609" quat="1.0 0.0 0.0 0.0" mass="0.00000001" diaginertia="1e-11 1e-11 1e-11"/>
            <geom name="xhand_right-right_hand_pinkyback_link2_collision" pos="0 0 0" quat="1.0 0.0 0.0 0.0" type="mesh" mesh="xhand_right-right_hand_pinkyback_link2.STL" class="xhand_right-collision"/>
            <geom name="xhand_right-right_hand_pinkyback_link2_visual" pos="0 0 0" quat="1.0 0.0 0.0 0.0" material="xhand_right-RAL_9003_Signal_White" type="mesh" mesh="xhand_right-right_hand_pinkyback_link2.STL" class="xhand_right-visual"/>
          </body>
          <body name="xhand_right-right_hand_pinky_tip" pos="0 0 -0.0422482924089404" quat="1.0 0.0 0.0 0.0">
            <inertial pos="6.17561557447743E-16 8.67361737988404E-18 0" quat="1.0 0.0 0.0 0.0" mass="0.00000565" diaginertia="1e-11 1e-11 1e-11"/>
            <geom name="xhand_right-right_hand_pinky_tip_collision" pos="0 0 0" quat="1.0 0.0 0.0 0.0" type="mesh" mesh="xhand_right-right_hand_pinky_tip.STL" class="xhand_right-collision"/>
            <geom name="xhand_right-right_hand_pinky_tip_visual" pos="0 0 0" quat="1.0 0.0 0.0 0.0" material="xhand_right-RAL_9005_Jet_Black" type="mesh" mesh="xhand_right-right_hand_pinky_tip.STL" class="xhand_right-visual"/>
          </body>
        </body>
      </body>
      <site name="xhand_right-right_hand_link_site" pos="0 0 0" quat="1 0 0 0"/>
      <camera name="xhand_right-front_camera" mode="track" fovy="90.0" quat="4.329780281177467e-17 4.329780281177466e-17 0.7071067811865475 0.7071067811865476" pos="0.0 2.0 0.5"/>
      <camera name="xhand_right-side_camera" mode="track" fovy="90.0" quat="-0.5 -0.4999999999999999 0.5 0.5000000000000001" pos="-2.0 0.0 0.5"/>
    </body>
    <body mocap="true" name="xhand_right-right-wrist" pos="0.0 0.0 0.20624829">
      <site pos="0 0 0" name="xhand_right-right-wrist-site-mocap" rgba="0.658 0.411 0.75 1" size=".01" type="sphere"/>
    </body>
    <body mocap="true" name="xhand_right-right-index-finger-tip" pos="0.026500000000000006 -0.21274829 0.20574829240894163" quat="0 -0.7071 -0.7071 0">
      <site pos="0 0 0" name="xhand_right-right-index-finger-tip-site-mocap" rgba="0.658 0.411 0.75 1" size=".01" type="sphere"/>
    </body>
    <body mocap="true" name="xhand_right-right-middle-finger-tip" pos="0.004000000000000001 -0.21274829 0.20624829240894177" quat="0 -0.7071 -0.7071 0">
      <site pos="0 0 0" name="xhand_right-right-middle-finger-tip-site-mocap" rgba="0.658 0.411 0.75 1" size=".01" type="sphere"/>
    </body>
    <body mocap="true" name="xhand_right-right-ring-finger-tip" pos="-0.016000000000000004 -0.21274829 0.20324829240894035" quat="0 -0.7071 -0.7071 0">
      <site pos="0 0 0" name="xhand_right-right-ring-finger-tip-site-mocap" rgba="0.658 0.411 0.75 1" size=".01" type="sphere"/>
    </body>
    <body mocap="true" name="xhand_right-right-pinky-finger-tip" pos="-0.036000000000000004 -0.21274829 0.20024829240894046" quat="0 -0.7071 -0.7071 0">
      <site pos="0 0 0" name="xhand_right-right-pinky-finger-tip-site-mocap" rgba="0.658 0.411 0.75 1" size=".01" type="sphere"/>
    </body>
    <body mocap="true" name="xhand_right-right-thumb-tip" pos="0.15200000000000002 -0.22500000000000006 0.02872000000000001" quat="0.6533 -0.2706 -0.6533 -0.2706">
      <site name="xhand_right-right-thumb-tip-site-mocap" rgba="0.658 0.411 0.75 1" size=".01" type="sphere"/>
    </body>
  </worldbody>
  <actuator>
    <motor name="xhand_right-right_hand_thumb_bend_joint_ctrl" joint="xhand_right-right_hand_thumb_bend_joint" class="xhand_right-motor"/>
    <motor name="xhand_right-right_hand_thumb_rota_joint1_ctrl" joint="xhand_right-right_hand_thumb_rota_joint1" class="xhand_right-motor"/>
    <motor name="xhand_right-right_hand_thumb_rota_joint2_ctrl" joint="xhand_right-right_hand_thumb_rota_joint2" class="xhand_right-motor"/>
    <motor name="xhand_right-right_hand_index_bend_joint_ctrl" joint="xhand_right-right_hand_index_bend_joint" class="xhand_right-motor"/>
    <motor name="xhand_right-right_hand_index_joint1_ctrl" joint="xhand_right-right_hand_index_joint1" class="xhand_right-motor"/>
    <motor name="xhand_right-right_hand_index_joint2_ctrl" joint="xhand_right-right_hand_index_joint2" class="xhand_right-motor"/>
    <motor name="xhand_right-right_hand_mid_joint1_ctrl" joint="xhand_right-right_hand_mid_joint1" class="xhand_right-motor"/>
    <motor name="xhand_right-right_hand_mid_joint2_ctrl" joint="xhand_right-right_hand_mid_joint2" class="xhand_right-motor"/>
    <motor name="xhand_right-right_hand_ring_joint1_ctrl" joint="xhand_right-right_hand_ring_joint1" class="xhand_right-motor"/>
    <motor name="xhand_right-right_hand_ring_joint2_ctrl" joint="xhand_right-right_hand_ring_joint2" class="xhand_right-motor"/>
    <motor name="xhand_right-right_hand_pinky_joint1_ctrl" joint="xhand_right-right_hand_pinky_joint1" class="xhand_right-motor"/>
    <motor name="xhand_right-right_hand_pinky_joint2_ctrl" joint="xhand_right-right_hand_pinky_joint2" class="xhand_right-motor"/>
  </actuator>
  <contact>
    <exclude body1="xhand_right" body2="xhand_right-right_hand_ee_link"/>
    <exclude body1="xhand_right" body2="xhand_right-right_hand_back_link"/>
    <exclude body1="xhand_right" body2="xhand_right-right_hand_thumb_bend_link"/>
    <exclude body1="xhand_right-right_hand_thumb_bend_link" body2="xhand_right-right_hand_thumb_rota_link1"/>
    <exclude body1="xhand_right-right_hand_thumb_rota_link1" body2="xhand_right-right_hand_thumb_rotaback_link1"/>
    <exclude body1="xhand_right-right_hand_thumb_rota_link1" body2="xhand_right-right_hand_thumb_rota_link2"/>
    <exclude body1="xhand_right-right_hand_thumb_rota_link2" body2="xhand_right-right_hand_thumb_rotaback_link2"/>
    <exclude body1="xhand_right-right_hand_thumb_rota_link2" body2="xhand_right-right_hand_thumb_rota_tip"/>
    <exclude body1="xhand_right" body2="xhand_right-right_hand_index_bend_link"/>
    <exclude body1="xhand_right-right_hand_index_bend_link" body2="xhand_right-right_hand_index_rota_link1"/>
    <exclude body1="xhand_right-right_hand_index_rota_link1" body2="xhand_right-right_hand_index_rotaback_link1"/>
    <exclude body1="xhand_right-right_hand_index_rota_link1" body2="xhand_right-right_hand_index_rota_link2"/>
    <exclude body1="xhand_right-right_hand_index_rota_link2" body2="xhand_right-right_hand_index_rotaback_link2"/>
    <exclude body1="xhand_right-right_hand_index_rota_link2" body2="xhand_right-right_hand_index_rota_tip"/>
    <exclude body1="xhand_right" body2="xhand_right-right_hand_mid_link1"/>
    <exclude body1="xhand_right-right_hand_mid_link1" body2="xhand_right-right_hand_midback_link1"/>
    <exclude body1="xhand_right-right_hand_mid_link1" body2="xhand_right-right_hand_mid_link2"/>
    <exclude body1="xhand_right-right_hand_mid_link2" body2="xhand_right-right_hand_midback_link2"/>
    <exclude body1="xhand_right-right_hand_mid_link2" body2="xhand_right-right_hand_mid_tip"/>
    <exclude body1="xhand_right" body2="xhand_right-right_hand_ring_link1"/>
    <exclude body1="xhand_right-right_hand_ring_link1" body2="xhand_right-right_hand_ringback_link1"/>
    <exclude body1="xhand_right-right_hand_ring_link1" body2="xhand_right-right_hand_ring_link2"/>
    <exclude body1="xhand_right-right_hand_ring_link2" body2="xhand_right-right_hand_ringback_link2"/>
    <exclude body1="xhand_right-right_hand_ring_link2" body2="xhand_right-right_hand_ring_tip"/>
    <exclude body1="xhand_right" body2="xhand_right-right_hand_pinky_link1"/>
    <exclude body1="xhand_right-right_hand_pinky_link1" body2="xhand_right-right_hand_pinkyback_link1"/>
    <exclude body1="xhand_right-right_hand_pinky_link1" body2="xhand_right-right_hand_pinky_link2"/>
    <exclude body1="xhand_right-right_hand_pinky_link2" body2="xhand_right-right_hand_pinkyback_link2"/>
    <exclude body1="xhand_right-right_hand_pinky_link2" body2="xhand_right-right_hand_pinky_tip"/>
  </contact>
  <sensor>
    <framepos name="xhand_right-right_hand_link_site_pos" objtype="site" objname="xhand_right-right_hand_link_site"/>
    <framequat name="xhand_right-right_hand_link_site_quat" objtype="site" objname="xhand_right-right_hand_link_site"/>
    <framelinvel name="xhand_right-right_hand_link_site_linvel" objtype="site" objname="xhand_right-right_hand_link_site"/>
    <frameangvel name="xhand_right-right_hand_link_site_angvel" objtype="site" objname="xhand_right-right_hand_link_site"/>
    <velocimeter name="xhand_right-right_hand_link_site_vel" site="xhand_right-right_hand_link_site"/>
  </sensor>
  <equality>
    <weld body1="xhand_right" body2="xhand_right-right-wrist"/>
    <weld body1="xhand_right-right_hand_index_rota_tip" body2="xhand_right-right-index-finger-tip"/>
    <weld body1="xhand_right-right_hand_mid_tip" body2="xhand_right-right-middle-finger-tip"/>
    <weld body1="xhand_right-right_hand_ring_tip" body2="xhand_right-right-ring-finger-tip"/>
    <weld body1="xhand_right-right_hand_pinky_tip" body2="xhand_right-right-pinky-finger-tip"/>
    <weld body1="xhand_right-right_hand_thumb_rota_tip" body2="xhand_right-right-thumb-tip"/>
    /
  </equality>
</mujoco>