<?xml version="1.0" ?>
<mujoco>
  <compiler angle="radian"/>
  <option iterations="5" ls_iterations="8" timestep=".004" integrator="implicitfast">
    <flag eulerdamp="disable"/>
  </option>
  <default>
    <default class="g1-g1">
      <default class="g1-visual">
        <geom group="2" type="mesh" density="0" material="g1-silver"/>
      </default>
      <default class="g1-collision">
        <geom group="3" rgba=".2 .6 .2 .3" type="capsule"/>
        <default class="g1-foot_box">
          <geom pos="0.04 0 -0.029" size="0.09 0.03 0.008" type="box" group="4"/>
        </default>
        <default class="g1-foot_capsule">
          <geom group="3" type="capsule" size="0.01"/>
        </default>
      </default>
      <site group="5" rgba="1 0 0 1"/>
      <!--Disable all contacts and use explicit contact pairs.-->
      <geom condim="1" contype="0" conaffinity="0"/>
      <joint frictionloss="0.1" solimplimit="0 0.99 0.01" solreflimit=".008 1"/>
      <position inheritrange="1" kp="75" kv="2"/>
      <default class="g1-hip">
        <default class="g1-hip_pitch">
          <joint axis="0 1 0" range="-2.5307 2.8798" actuatorfrcrange="-88 88" armature="0.01017752004"/>
        </default>
        <default class="g1-hip_roll">
          <joint axis="1 0 0" range="-0.5236 2.9671" actuatorfrcrange="-139 139" armature="0.025101925"/>
        </default>
        <default class="g1-hip_yaw">
          <joint axis="0 0 1" range="-2.7576 2.7576" actuatorfrcrange="-88 88" armature="0.01017752004"/>
        </default>
      </default>
      <default class="g1-knee">
        <joint axis="0 1 0" range="-0.087267 2.8798" actuatorfrcrange="-139 139" armature="0.025101925"/>
      </default>
      <default class="g1-ankle">
        <position kp="20" kv="2"/>
        <default class="g1-ankle_pitch">
          <joint axis="0 1 0" range="-0.87267 0.5236" actuatorfrcrange="-50 50" armature="0.00721945"/>
        </default>
        <default class="g1-ankle_roll">
          <joint axis="1 0 0" range="-0.2618 0.2618" actuatorfrcrange="-50 50" armature="0.00721945"/>
        </default>
      </default>
      <default class="g1-waist_yaw">
        <joint axis="0 0 1" range="-2.618 2.618" actuatorfrcrange="-88 88" armature="0.01017752004"/>
      </default>
      <default class="g1-waist_pitch">
        <joint axis="0 1 0" range="-0.52 0.52" actuatorfrcrange="-50 50" armature="0.00721945"/>
      </default>
      <default class="g1-waist_roll">
        <joint axis="1 0 0" range="-0.52 0.52" actuatorfrcrange="-50 50" armature="0.00721945"/>
      </default>
      <default class="g1-shoulder">
        <default class="g1-shoulder_pitch">
          <joint axis="0 1 0" range="-3.0892 2.6704" actuatorfrcrange="-25 25" armature="0.003609725"/>
        </default>
        <default class="g1-shoulder_roll">
          <joint axis="1 0 0" actuatorfrcrange="-25 25" armature="0.003609725"/>
        </default>
        <default class="g1-shoulder_yaw">
          <joint axis="0 0 1" range="-2.618 2.618" actuatorfrcrange="-25 25" armature="0.003609725"/>
        </default>
      </default>
      <default class="g1-elbow">
        <joint axis="0 1 0" range="-1.0472 2.0944" actuatorfrcrange="-25 25" armature="0.003609725"/>
      </default>
      <default class="g1-wrist">
        <position kp="20" kv="2"/>
        <default class="g1-wrist_roll">
          <joint axis="1 0 0" range="-1.97222 1.97222" actuatorfrcrange="-25 25" armature="0.003609725"/>
        </default>
        <default class="g1-wrist_pitch">
          <joint axis="0 1 0" range="-1.61443 1.61443" actuatorfrcrange="-5 5" armature="0.00425"/>
        </default>
        <default class="g1-wrist_yaw">
          <joint axis="0 0 1" range="-1.61443 1.61443" actuatorfrcrange="-5 5" armature="0.00425"/>
        </default>
      </default>
    </default>
  </default>
  <asset>
    <material name="g1-silver" rgba="0.7 0.7 0.7 1"/>
    <material name="g1-black" rgba="0.2 0.2 0.2 1"/>
    <mesh name="g1-pelvis" file="./pelvis.STL"/>
    <mesh name="g1-pelvis_contour_link" file="./pelvis_contour_link.STL"/>
    <mesh name="g1-left_hip_pitch_link" file="./left_hip_pitch_link.STL"/>
    <mesh name="g1-left_hip_roll_link" file="./left_hip_roll_link.STL"/>
    <mesh name="g1-left_hip_yaw_link" file="./left_hip_yaw_link.STL"/>
    <mesh name="g1-left_knee_link" file="./left_knee_link.STL"/>
    <mesh name="g1-left_ankle_pitch_link" file="./left_ankle_pitch_link.STL"/>
    <mesh name="g1-left_ankle_roll_link" file="./left_ankle_roll_link.STL"/>
    <mesh name="g1-right_hip_pitch_link" file="./right_hip_pitch_link.STL"/>
    <mesh name="g1-right_hip_roll_link" file="./right_hip_roll_link.STL"/>
    <mesh name="g1-right_hip_yaw_link" file="./right_hip_yaw_link.STL"/>
    <mesh name="g1-right_knee_link" file="./right_knee_link.STL"/>
    <mesh name="g1-right_ankle_pitch_link" file="./right_ankle_pitch_link.STL"/>
    <mesh name="g1-right_ankle_roll_link" file="./right_ankle_roll_link.STL"/>
    <mesh name="g1-waist_yaw_link" file="./waist_yaw_link_rev_1_0.STL"/>
    <mesh name="g1-waist_roll_link" file="./waist_roll_link_rev_1_0.STL"/>
    <mesh name="g1-torso_link" file="./torso_link_rev_1_0.STL"/>
    <mesh name="g1-logo_link" file="./logo_link.STL"/>
    <mesh name="g1-head_link" file="./head_link.STL"/>
    <mesh name="g1-left_shoulder_pitch_link" file="./left_shoulder_pitch_link.STL"/>
    <mesh name="g1-left_shoulder_roll_link" file="./left_shoulder_roll_link.STL"/>
    <mesh name="g1-left_shoulder_yaw_link" file="./left_shoulder_yaw_link.STL"/>
    <mesh name="g1-left_elbow_link" file="./left_elbow_link.STL"/>
    <mesh name="g1-left_wrist_roll_link" file="./left_wrist_roll_link.STL"/>
    <mesh name="g1-left_wrist_pitch_link" file="./left_wrist_pitch_link.STL"/>
    <mesh name="g1-left_wrist_yaw_link" file="./left_wrist_yaw_link.STL"/>
    <mesh name="g1-left_rubber_hand" file="./left_rubber_hand.STL"/>
    <mesh name="g1-right_shoulder_pitch_link" file="./right_shoulder_pitch_link.STL"/>
    <mesh name="g1-right_shoulder_roll_link" file="./right_shoulder_roll_link.STL"/>
    <mesh name="g1-right_shoulder_yaw_link" file="./right_shoulder_yaw_link.STL"/>
    <mesh name="g1-right_elbow_link" file="./right_elbow_link.STL"/>
    <mesh name="g1-right_wrist_roll_link" file="./right_wrist_roll_link.STL"/>
    <mesh name="g1-right_wrist_pitch_link" file="./right_wrist_pitch_link.STL"/>
    <mesh name="g1-right_wrist_yaw_link" file="./right_wrist_yaw_link.STL"/>
    <mesh name="g1-right_rubber_hand" file="./right_rubber_hand.STL"/>
    <mesh name="g1-right_hand_palm_link" file="./right_hand_palm_link.STL"/>
    <mesh name="g1-left_hand_palm_link" file="./left_hand_palm_link.STL"/>
    <mesh name="g1-right_hand_thumb_0_link" file="./right_hand_thumb_0_link.STL"/>
    <mesh name="g1-right_hand_thumb_1_link" file="./right_hand_thumb_1_link.STL"/>
    <mesh name="g1-right_hand_thumb_2_link" file="./right_hand_thumb_2_link.STL"/>
    <mesh name="g1-left_hand_thumb_0_link" file="./left_hand_thumb_0_link.STL"/>
    <mesh name="g1-left_hand_thumb_1_link" file="./left_hand_thumb_1_link.STL"/>
    <mesh name="g1-left_hand_thumb_2_link" file="./left_hand_thumb_2_link.STL"/>
    <mesh name="g1-right_hand_middle_0_link" file="./right_hand_middle_0_link.STL"/>
    <mesh name="g1-right_hand_middle_1_link" file="./right_hand_middle_1_link.STL"/>
    <mesh name="g1-left_hand_middle_0_link" file="./left_hand_middle_0_link.STL"/>
    <mesh name="g1-left_hand_middle_1_link" file="./left_hand_middle_1_link.STL"/>
    <mesh name="g1-left_hand_index_0_link" file="./left_hand_index_0_link.STL"/>
    <mesh name="g1-left_hand_index_1_link" file="./left_hand_index_1_link.STL"/>
    <mesh name="g1-right_hand_index_0_link" file="./right_hand_index_0_link.STL"/>
    <mesh name="g1-right_hand_index_1_link" file="./right_hand_index_1_link.STL"/>
  </asset>
  <worldbody>
    <body name="g1-pelvis" pos="0 0 0.793" childclass="g1-g1">
      <camera name="g1-track" pos="1.734 -1.135 .35" xyaxes="0.552 0.834 -0.000 -0.170 0.112 0.979" mode="trackcom"/>
      <inertial pos="0 0 -0.07605" quat="1 0 -0.000399148 0" mass="3.813" diaginertia="0.010549 0.0093089 0.0079184"/>
      <freejoint name="g1-floating_base_joint"/>
      <geom class="g1-visual" material="g1-black" mesh="g1-pelvis"/>
      <geom class="g1-visual" mesh="g1-pelvis_contour_link"/>
      <geom name="g1-pelvis_collision" class="g1-collision" type="sphere" size="0.07" pos="0 0 -0.08"/>
      <site name="g1-imu_in_pelvis" size="0.01" pos="0.04525 0 -0.08339"/>
      <body name="g1-left_hip_pitch_link" pos="0 0.064452 -0.1027">
        <inertial pos="0.002741 0.047791 -0.02606" quat="0.954862 0.293964 0.0302556 0.030122" mass="1.35" diaginertia="0.00181517 0.00153422 0.00116212"/>
        <joint name="g1-left_hip_pitch_joint" class="g1-hip_pitch"/>
        <geom class="g1-visual" material="g1-black" mesh="g1-left_hip_pitch_link"/>
        <body name="g1-left_hip_roll_link" pos="0 0.052 -0.030465" quat="0.996179 0 -0.0873386 0">
          <inertial pos="0.029812 -0.001045 -0.087934" quat="0.977808 -1.97119e-05 0.205576 -0.0403793" mass="1.52" diaginertia="0.00254986 0.00241169 0.00148755"/>
          <joint name="g1-left_hip_roll_joint" class="g1-hip_roll"/>
          <geom class="g1-visual" mesh="g1-left_hip_roll_link"/>
          <geom name="g1-left_hip_collision" class="g1-collision" size="0.06" fromto="0.02 0 0 0.02 0 -0.08"/>
          <body name="g1-left_hip_yaw_link" pos="0.025001 0 -0.12412">
            <inertial pos="-0.057709 -0.010981 -0.15078" quat="0.600598 0.15832 0.223482 0.751181" mass="1.702" diaginertia="0.00776166 0.00717575 0.00160139"/>
            <joint name="g1-left_hip_yaw_joint" class="g1-hip_yaw"/>
            <geom class="g1-visual" mesh="g1-left_hip_yaw_link"/>
            <geom name="g1-left_thigh_collision" class="g1-collision" size="0.055" fromto="-0.0 0 -0.03 -0.06 0 -0.17"/>
            <body name="g1-left_knee_link" pos="-0.078273 0.0021489 -0.17734" quat="0.996179 0 0.0873386 0">
              <inertial pos="0.005457 0.003964 -0.12074" quat="0.923418 -0.0327699 0.0158246 0.382067" mass="1.932" diaginertia="0.0113804 0.0112778 0.00146458"/>
              <joint name="g1-left_knee_joint" class="g1-knee"/>
              <geom class="g1-visual" mesh="g1-left_knee_link"/>
              <geom name="g1-left_shin_collision" class="g1-collision" size="0.045" fromto="0.01 0 0 0.01 0 -0.15"/>
              <geom name="g1-left_linkage_brace_collision" class="g1-collision" size="0.03" fromto="0.01 0 -0.2 0.01 0 -0.28"/>
              <body name="g1-left_ankle_pitch_link" pos="0 -9.4445e-05 -0.30001">
                <inertial pos="-0.007269 0 0.011137" quat="0.603053 0.369225 0.369225 0.603053" mass="0.074" diaginertia="1.89e-05 1.40805e-05 6.9195e-06"/>
                <joint name="g1-left_ankle_pitch_joint" class="g1-ankle_pitch"/>
                <geom class="g1-visual" mesh="g1-left_ankle_pitch_link"/>
                <body name="g1-left_ankle_roll_link" pos="0 0 -0.017558">
                  <site name="g1-left_foot" rgba="1 0 0 1" pos="0.04 0 -0.037"/>
                  <inertial pos="0.026505 0 -0.016425" quat="-0.000481092 0.728482 -0.000618967 0.685065" mass="0.608" diaginertia="0.00167218 0.0016161 0.000217621"/>
                  <joint name="g1-left_ankle_roll_joint" class="g1-ankle_roll"/>
                  <geom class="g1-visual" material="g1-black" mesh="g1-left_ankle_roll_link"/>
                  <geom name="g1-left_foot_box_collision" class="g1-foot_box"/>
                  <geom name="g1-left_foot1_collision" class="g1-foot_capsule" fromto="0.1 -0.026 -0.025 0.05 -0.027 -0.025"/>
                  <geom name="g1-left_foot2_collision" class="g1-foot_capsule" fromto="-0.045 0 -0.015 0.12 0 -0.015" size="0.02"/>
                  <geom name="g1-left_foot3_collision" class="g1-foot_capsule" fromto="0.1 0.026 -0.025 0.05 0.026 -0.025"/>
                </body>
              </body>
            </body>
          </body>
        </body>
      </body>
      <body name="g1-right_hip_pitch_link" pos="0 -0.064452 -0.1027">
        <inertial pos="0.002741 -0.047791 -0.02606" quat="0.954862 -0.293964 0.0302556 -0.030122" mass="1.35" diaginertia="0.00181517 0.00153422 0.00116212"/>
        <joint name="g1-right_hip_pitch_joint" class="g1-hip_pitch"/>
        <geom class="g1-visual" material="g1-black" mesh="g1-right_hip_pitch_link"/>
        <body name="g1-right_hip_roll_link" pos="0 -0.052 -0.030465" quat="0.996179 0 -0.0873386 0">
          <inertial pos="0.029812 0.001045 -0.087934" quat="0.977808 1.97119e-05 0.205576 0.0403793" mass="1.52" diaginertia="0.00254986 0.00241169 0.00148755"/>
          <joint name="g1-right_hip_roll_joint" class="g1-hip_roll"/>
          <geom class="g1-visual" mesh="g1-right_hip_roll_link"/>
          <geom name="g1-right_hip_collision" class="g1-collision" size="0.06" fromto="0.02 0 0 0.02 0 -0.08"/>
          <body name="g1-right_hip_yaw_link" pos="0.025001 0 -0.12412">
            <inertial pos="-0.057709 0.010981 -0.15078" quat="0.751181 0.223482 0.15832 0.600598" mass="1.702" diaginertia="0.00776166 0.00717575 0.00160139"/>
            <joint name="g1-right_hip_yaw_joint" class="g1-hip_yaw"/>
            <geom class="g1-visual" mesh="g1-right_hip_yaw_link"/>
            <geom name="g1-right_thigh_collision" class="g1-collision" size="0.055" fromto="-0.0 0 -0.03 -0.06 0 -0.17"/>
            <body name="g1-right_knee_link" pos="-0.078273 -0.0021489 -0.17734" quat="0.996179 0 0.0873386 0">
              <inertial pos="0.005457 -0.003964 -0.12074" quat="0.923439 0.0345276 0.0116333 -0.382012" mass="1.932" diaginertia="0.011374 0.0112843 0.00146452"/>
              <joint name="g1-right_knee_joint" class="g1-knee"/>
              <geom class="g1-visual" mesh="g1-right_knee_link"/>
              <geom name="g1-right_shin_collision" class="g1-collision" size="0.045" fromto="0.01 0 0 0.01 0 -0.15"/>
              <geom name="g1-right_linkage_brace_collision" class="g1-collision" size="0.03" fromto="0.01 0 -0.2 0.01 0 -0.28"/>
              <body name="g1-right_ankle_pitch_link" pos="0 9.4445e-05 -0.30001">
                <inertial pos="-0.007269 0 0.011137" quat="0.603053 0.369225 0.369225 0.603053" mass="0.074" diaginertia="1.89e-05 1.40805e-05 6.9195e-06"/>
                <joint name="g1-right_ankle_pitch_joint" class="g1-ankle_pitch"/>
                <geom class="g1-visual" mesh="g1-right_ankle_pitch_link"/>
                <body name="g1-right_ankle_roll_link" pos="0 0 -0.017558">
                  <site name="g1-right_foot" rgba="1 0 0 1" pos="0.04 0 -0.037"/>
                  <inertial pos="0.026505 0 -0.016425" quat="0.000481092 0.728482 0.000618967 0.685065" mass="0.608" diaginertia="0.00167218 0.0016161 0.000217621"/>
                  <joint name="g1-right_ankle_roll_joint" class="g1-ankle_roll"/>
                  <geom class="g1-visual" material="g1-black" mesh="g1-right_ankle_roll_link"/>
                  <geom name="g1-right_foot_box_collision" class="g1-foot_box"/>
                  <geom name="g1-right_foot1_collision" class="g1-foot_capsule" fromto="0.1 -0.026 -0.025 0.05 -0.026 -0.025"/>
                  <geom name="g1-right_foot2_collision" class="g1-foot_capsule" fromto="-0.045 0 -0.015 0.12 0 -0.015" size="0.02"/>
                  <geom name="g1-right_foot3_collision" class="g1-foot_capsule" fromto="0.1 0.026 -0.025 0.05 0.026 -0.025"/>
                </body>
              </body>
            </body>
          </body>
        </body>
      </body>
      <body name="g1-waist_yaw_link">
        <inertial pos="0.003494 0.000233 0.018034" quat="0.289697 0.591001 -0.337795 0.672821" mass="0.214" diaginertia="0.000163531 0.000107714 0.000102205"/>
        <joint name="g1-waist_yaw_joint" class="g1-waist_yaw"/>
        <geom class="g1-visual" mesh="g1-waist_yaw_link"/>
        <body name="g1-waist_roll_link" pos="-0.0039635 0 0.044">
          <inertial pos="0 2.3e-05 0" quat="0.5 0.5 -0.5 0.5" mass="0.086" diaginertia="8.245e-06 7.079e-06 6.339e-06"/>
          <joint name="g1-waist_roll_joint" class="g1-waist_roll"/>
          <geom class="g1-visual" mesh="g1-waist_roll_link"/>
          <body name="g1-torso_link">
            <inertial pos="0.00203158 0.000339683 0.184568" quat="0.999803 -6.03319e-05 0.0198256 0.00131986" mass="7.818" diaginertia="0.121847 0.109825 0.0273735"/>
            <joint name="g1-waist_pitch_joint" class="g1-waist_pitch"/>
            <geom class="g1-visual" mesh="g1-torso_link"/>
            <geom pos="0.0039635 0 -0.044" quat="1 0 0 0" class="g1-visual" material="g1-black" mesh="g1-logo_link"/>
            <geom pos="0.0039635 0 -0.044" class="g1-visual" material="g1-black" mesh="g1-head_link"/>
            <geom name="g1-torso_collision" class="g1-collision" size="0.09" fromto="0.01 0 0.08 0.01 0 0.2"/>
            <geom name="g1-head_collision" class="g1-collision" type="sphere" size="0.06" pos="0 0 .43"/>
            <site name="g1-imu_in_torso" size="0.01" pos="-0.03959 -0.00224 0.14792"/>
            <body name="g1-left_shoulder_pitch_link" pos="0.0039563 0.10022 0.24778" quat="0.990264 0.139201 1.38722e-05 -9.86868e-05">
              <inertial pos="0 0.035892 -0.011628" quat="0.654152 0.0130458 -0.326267 0.68225" mass="0.718" diaginertia="0.000465864 0.000432842 0.000406394"/>
              <joint name="g1-left_shoulder_pitch_joint" class="g1-shoulder_pitch"/>
              <geom class="g1-visual" mesh="g1-left_shoulder_pitch_link"/>
              <body name="g1-left_shoulder_roll_link" pos="0 0.038 -0.013831" quat="0.990268 -0.139172 0 0">
                <inertial pos="-0.000227 0.00727 -0.063243" quat="0.701256 -0.0196223 -0.00710317 0.712604" mass="0.643" diaginertia="0.000691311 0.000618011 0.000388977"/>
                <joint name="g1-left_shoulder_roll_joint" range="-1.5882 2.2515" class="g1-shoulder_roll"/>
                <geom class="g1-visual" mesh="g1-left_shoulder_roll_link"/>
                <body name="g1-left_shoulder_yaw_link" pos="0 0.00624 -0.1032">
                  <inertial pos="0.010773 -0.002949 -0.072009" quat="0.716879 -0.0964829 -0.0679942 0.687134" mass="0.734" diaginertia="0.00106187 0.00103217 0.000400661"/>
                  <joint name="g1-left_shoulder_yaw_joint" class="g1-shoulder_yaw"/>
                  <geom class="g1-visual" mesh="g1-left_shoulder_yaw_link"/>
                  <geom name="g1-left_shoulder_yaw_collision" class="g1-collision" size="0.035" fromto="0 0 -0.08 0 0 0.05"/>
                  <body name="g1-left_elbow_link" pos="0.015783 0 -0.080518">
                    <inertial pos="0.064956 0.004454 -0.010062" quat="0.541765 0.636132 0.388821 0.388129" mass="0.6" diaginertia="0.000443035 0.000421612 0.000259353"/>
                    <joint name="g1-left_elbow_joint" class="g1-elbow"/>
                    <geom class="g1-visual" mesh="g1-left_elbow_link"/>
                    <geom name="g1-left_elbow_yaw_collision" class="g1-collision" size="0.035" fromto="-0.01 0 -0.01 0.08 0 -0.01"/>
                    <body name="g1-left_wrist_roll_link" pos="0.1 0.00188791 -0.01">
                      <inertial pos="0.0171394 0.000537591 4.8864e-07" quat="0.575338 0.411667 -0.574906 0.411094" mass="0.085445" diaginertia="5.48211e-05 4.96646e-05 3.57798e-05"/>
                      <joint name="g1-left_wrist_roll_joint" class="g1-wrist_roll"/>
                      <geom class="g1-visual" mesh="g1-left_wrist_roll_link"/>
                      <body name="g1-left_wrist_pitch_link" pos="0.038 0 0">
                        <inertial pos="0.0229999 -0.00111685 -0.00111658" quat="0.249998 0.661363 0.293036 0.643608" mass="0.48405" diaginertia="0.000430353 0.000429873 0.000164648"/>
                        <joint name="g1-left_wrist_pitch_joint" class="g1-wrist_pitch"/>
                        <geom class="g1-visual" mesh="g1-left_wrist_pitch_link"/>
                        <geom name="g1-left_wrist_collision" class="g1-collision" size="0.035" fromto="-0.01 0 0 0.06 0 0"/>
                        <body name="g1-left_wrist_yaw_link" pos="0.046 0 0">
                          <site name="g1-left_palm" pos="0 0 0" size="0.01"/>
                          <inertial pos="0.0885506 0.00212216 -0.000374562" quat="0.487149 0.493844 0.513241 0.505358" mass="0.457415" diaginertia="0.00105989 0.000895419 0.000323842"/>
                          <joint name="g1-left_wrist_yaw_joint" axis="0 0 1" range="-1.61443 1.61443" actuatorfrcrange="-5 5"/>
                          <geom class="g1-visual" mesh="g1-left_wrist_yaw_link"/>
                          <geom class="g1-collision" mesh="g1-left_wrist_yaw_link"/>
                          <geom pos="0.0415 0.003 0" quat="1 0 0 0" class="g1-visual" mesh="g1-left_hand_palm_link"/>
                          <geom pos="0.0415 0.003 0" quat="1 0 0 0" class="g1-collision" mesh="g1-left_hand_palm_link"/>
                          <body name="g1-left_hand_thumb_0_link" pos="0.067 0.003 0">
                            <inertial pos="-0.000884246 -0.00863407 0.000944293" quat="0.462991 0.643965 -0.460173 0.398986" mass="0.0862366" diaginertia="1.6546e-05 1.60058e-05 1.43741e-05"/>
                            <joint name="g1-left_hand_thumb_0_joint" axis="0 1 0" range="-1.0472 1.0472" actuatorfrcrange="-2.45 2.45"/>
                            <geom class="g1-visual" mesh="g1-left_hand_thumb_0_link"/>
                            <geom class="g1-collision" mesh="g1-left_hand_thumb_0_link"/>
                            <body name="g1-left_hand_thumb_1_link" pos="-0.0025 -0.0193 0">
                              <inertial pos="-0.000827888 -0.0354744 -0.0003809" quat="0.685598 0.705471 -0.15207 0.0956069" mass="0.0588507" diaginertia="1.28514e-05 1.22902e-05 5.9666e-06"/>
                              <joint name="g1-left_hand_thumb_1_joint" axis="0 0 1" range="-0.724312 1.0472" actuatorfrcrange="-1.4 1.4"/>
                              <geom class="g1-visual" mesh="g1-left_hand_thumb_1_link"/>
                              <geom size="0.01 0.015 0.01" pos="-0.001 -0.032 0" type="box" class="g1-collision"/>
                              <body name="g1-left_hand_thumb_2_link" pos="0 -0.0458 0">
                                <site name="g1-left_thumb" pos="0.0 -0.04 0.0" size="0.01"/>
                                <inertial pos="-0.00171735 -0.0262819 0.000107789" quat="0.703174 0.710977 -0.00017564 -0.00766553" mass="0.0203063" diaginertia="4.61314e-06 3.86645e-06 1.53495e-06"/>
                                <joint name="g1-left_hand_thumb_2_joint" axis="0 0 1" range="0 1.74533" actuatorfrcrange="-1.4 1.4"/>
                                <geom class="g1-visual" mesh="g1-left_hand_thumb_2_link"/>
                                <geom class="g1-collision" mesh="g1-left_hand_thumb_2_link"/>
                              </body>
                            </body>
                          </body>
                          <body name="g1-left_hand_middle_0_link" pos="0.1192 0.0046 -0.0285">
                            <inertial pos="0.0354744 0.000827888 0.0003809" quat="0.391313 0.552395 0.417187 0.606373" mass="0.0588507" diaginertia="1.28514e-05 1.22902e-05 5.9666e-06"/>
                            <joint name="g1-left_hand_middle_0_joint" axis="0 0 1" range="-1.5708 0" actuatorfrcrange="-1.4 1.4"/>
                            <geom class="g1-visual" mesh="g1-left_hand_middle_0_link"/>
                            <geom class="g1-collision" mesh="g1-left_hand_middle_0_link"/>
                            <body name="g1-left_hand_middle_1_link" pos="0.0458 0 0">
                              <site name="g1-left_middle" pos="0.04 0 0" size="0.01"/>
                              <inertial pos="0.0262819 0.00171735 -0.000107789" quat="0.502612 0.491799 0.502639 0.502861" mass="0.0203063" diaginertia="4.61314e-06 3.86645e-06 1.53495e-06"/>
                              <joint name="g1-left_hand_middle_1_joint" axis="0 0 1" range="-1.74533 0" actuatorfrcrange="-1.4 1.4"/>
                              <geom class="g1-visual" mesh="g1-left_hand_middle_1_link"/>
                              <geom class="g1-collision" mesh="g1-left_hand_middle_1_link"/>
                            </body>
                          </body>
                          <body name="g1-left_hand_index_0_link" pos="0.1192 0.0046 0.0285">
                            <inertial pos="0.0354744 0.000827888 0.0003809" quat="0.391313 0.552395 0.417187 0.606373" mass="0.0588507" diaginertia="1.28514e-05 1.22902e-05 5.9666e-06"/>
                            <joint name="g1-left_hand_index_0_joint" axis="0 0 1" range="-1.5708 0" actuatorfrcrange="-1.4 1.4"/>
                            <geom class="g1-visual" mesh="g1-left_hand_index_0_link"/>
                            <geom class="g1-collision" mesh="g1-left_hand_index_0_link"/>
                            <body name="g1-left_hand_index_1_link" pos="0.0458 0 0">
                              <site name="g1-left_index" pos="0.04 0 0" size="0.01"/>
                              <inertial pos="0.0262819 0.00171735 -0.000107789" quat="0.502612 0.491799 0.502639 0.502861" mass="0.0203063" diaginertia="4.61314e-06 3.86645e-06 1.53495e-06"/>
                              <joint name="g1-left_hand_index_1_joint" axis="0 0 1" range="-1.74533 0" actuatorfrcrange="-1.4 1.4"/>
                              <geom class="g1-visual" mesh="g1-left_hand_index_1_link"/>
                              <geom class="g1-collision" mesh="g1-left_hand_index_1_link"/>
                            </body>
                          </body>
                        </body>
                      </body>
                    </body>
                  </body>
                </body>
              </body>
            </body>
            <body name="g1-right_shoulder_pitch_link" pos="0.0039563 -0.10021 0.24778" quat="0.990264 -0.139201 1.38722e-05 9.86868e-05">
              <inertial pos="0 -0.035892 -0.011628" quat="0.68225 -0.326267 0.0130458 0.654152" mass="0.718" diaginertia="0.000465864 0.000432842 0.000406394"/>
              <joint name="g1-right_shoulder_pitch_joint" class="g1-shoulder_pitch"/>
              <geom class="g1-visual" mesh="g1-right_shoulder_pitch_link"/>
              <body name="g1-right_shoulder_roll_link" pos="0 -0.038 -0.013831" quat="0.990268 0.139172 0 0">
                <inertial pos="-0.000227 -0.00727 -0.063243" quat="0.712604 -0.00710317 -0.0196223 0.701256" mass="0.643" diaginertia="0.000691311 0.000618011 0.000388977"/>
                <joint name="g1-right_shoulder_roll_joint" range="-2.2515 1.5882" class="g1-shoulder_roll"/>
                <geom class="g1-visual" mesh="g1-right_shoulder_roll_link"/>
                <body name="g1-right_shoulder_yaw_link" pos="0 -0.00624 -0.1032">
                  <inertial pos="0.010773 0.002949 -0.072009" quat="0.687134 -0.0679942 -0.0964829 0.716879" mass="0.734" diaginertia="0.00106187 0.00103217 0.000400661"/>
                  <joint name="g1-right_shoulder_yaw_joint" class="g1-shoulder_yaw"/>
                  <geom class="g1-visual" mesh="g1-right_shoulder_yaw_link"/>
                  <geom name="g1-right_shoulder_yaw_collision" class="g1-collision" size="0.035" fromto="0 0 -0.08 0 0 0.05"/>
                  <body name="g1-right_elbow_link" pos="0.015783 0 -0.080518">
                    <inertial pos="0.064956 -0.004454 -0.010062" quat="0.388129 0.388821 0.636132 0.541765" mass="0.6" diaginertia="0.000443035 0.000421612 0.000259353"/>
                    <joint name="g1-right_elbow_joint" class="g1-elbow"/>
                    <geom class="g1-visual" mesh="g1-right_elbow_link"/>
                    <geom name="g1-right_elbow_yaw_collision" class="g1-collision" size="0.035" fromto="-0.01 0 -0.01 0.08 0 -0.01"/>
                    <body name="g1-right_wrist_roll_link" pos="0.1 -0.00188791 -0.01">
                      <inertial pos="0.0171394 -0.000537591 4.8864e-07" quat="0.411667 0.575338 -0.411094 0.574906" mass="0.085445" diaginertia="5.48211e-05 4.96646e-05 3.57798e-05"/>
                      <joint name="g1-right_wrist_roll_joint" class="g1-wrist_roll"/>
                      <geom class="g1-visual" mesh="g1-right_wrist_roll_link"/>
                      <body name="g1-right_wrist_pitch_link" pos="0.038 0 0">
                        <inertial pos="0.0229999 0.00111685 -0.00111658" quat="0.643608 0.293036 0.661363 0.249998" mass="0.48405" diaginertia="0.000430353 0.000429873 0.000164648"/>
                        <joint name="g1-right_wrist_pitch_joint" class="g1-wrist_pitch"/>
                        <geom class="g1-visual" mesh="g1-right_wrist_pitch_link"/>
                        <geom name="g1-right_wrist_collision" class="g1-collision" size="0.035" fromto="-0.01 0 0 0.06 0 0"/>
                        <body name="g1-right_wrist_yaw_link" pos="0.046 0 0">
                          <site name="g1-right_palm" pos="0 0 0" size="0.01"/>
                          <inertial pos="0.0885506 -0.00212216 -0.000374562" quat="0.505358 0.513241 0.493844 0.487149" mass="0.457415" diaginertia="0.00105989 0.000895419 0.000323842"/>
                          <joint name="g1-right_wrist_yaw_joint" axis="0 0 1" range="-1.61443 1.61443" actuatorfrcrange="-5 5"/>
                          <geom class="g1-visual" mesh="g1-right_wrist_yaw_link"/>
                          <geom class="g1-collision" mesh="g1-right_wrist_yaw_link"/>
                          <geom pos="0.0415 -0.003 0" quat="1 0 0 0" class="g1-visual" mesh="g1-right_hand_palm_link"/>
                          <geom pos="0.0415 -0.003 0" quat="1 0 0 0" class="g1-collision" mesh="g1-right_hand_palm_link"/>
                          <body name="g1-right_hand_thumb_0_link" pos="0.067 -0.003 0">
                            <inertial pos="-0.000884246 0.00863407 0.000944293" quat="0.643965 0.462991 -0.398986 0.460173" mass="0.0862366" diaginertia="1.6546e-05 1.60058e-05 1.43741e-05"/>
                            <joint name="g1-right_hand_thumb_0_joint" axis="0 1 0" range="-1.0472 1.0472" actuatorfrcrange="-2.45 2.45"/>
                            <geom class="g1-visual" mesh="g1-right_hand_thumb_0_link"/>
                            <geom class="g1-collision" mesh="g1-right_hand_thumb_0_link"/>
                            <body name="g1-right_hand_thumb_1_link" pos="-0.0025 0.0193 0">
                              <inertial pos="-0.000827888 0.0354744 -0.0003809" quat="0.705471 0.685598 -0.0956069 0.15207" mass="0.0588507" diaginertia="1.28514e-05 1.22902e-05 5.9666e-06"/>
                              <joint name="g1-right_hand_thumb_1_joint" axis="0 0 1" range="-1.0472 0.724312" actuatorfrcrange="-1.4 1.4"/>
                              <geom class="g1-visual" mesh="g1-right_hand_thumb_1_link"/>
                              <geom size="0.01 0.015 0.01" pos="-0.001 0.032 0" type="box" class="g1-collision"/>
                              <body name="g1-right_hand_thumb_2_link" pos="0 0.0458 0">
                                <site name="g1-right_thumb" pos="0.0 0.04 0.0" size="0.01"/>
                                <inertial pos="-0.00171735 0.0262819 0.000107789" quat="0.710977 0.703174 0.00766553 0.00017564" mass="0.0203063" diaginertia="4.61314e-06 3.86645e-06 1.53495e-06"/>
                                <joint name="g1-right_hand_thumb_2_joint" axis="0 0 1" range="-1.74533 0" actuatorfrcrange="-1.4 1.4"/>
                                <geom class="g1-visual" mesh="g1-right_hand_thumb_2_link"/>
                                <geom class="g1-collision" mesh="g1-right_hand_thumb_2_link"/>
                              </body>
                            </body>
                          </body>
                          <body name="g1-right_hand_middle_0_link" pos="0.1192 -0.0046 -0.0285">
                            <inertial pos="0.0354744 -0.000827888 0.0003809" quat="0.606373 0.417187 0.552395 0.391313" mass="0.0588507" diaginertia="1.28514e-05 1.22902e-05 5.9666e-06"/>
                            <joint name="g1-right_hand_middle_0_joint" axis="0 0 1" range="0 1.5708" actuatorfrcrange="-1.4 1.4"/>
                            <geom class="g1-visual" mesh="g1-right_hand_middle_0_link"/>
                            <geom class="g1-collision" mesh="g1-right_hand_middle_0_link"/>
                            <body name="g1-right_hand_middle_1_link" pos="0.0458 0 0">
                              <site name="g1-right_middle" pos="0.04 0 0" size="0.01"/>
                              <inertial pos="0.0262819 -0.00171735 -0.000107789" quat="0.502861 0.502639 0.491799 0.502612" mass="0.0203063" diaginertia="4.61314e-06 3.86645e-06 1.53495e-06"/>
                              <joint name="g1-right_hand_middle_1_joint" axis="0 0 1" range="0 1.74533" actuatorfrcrange="-1.4 1.4"/>
                              <geom class="g1-visual" mesh="g1-right_hand_middle_1_link"/>
                              <geom class="g1-collision" mesh="g1-right_hand_middle_1_link"/>
                            </body>
                          </body>
                          <body name="g1-right_hand_index_0_link" pos="0.1192 -0.0046 0.0285">
                            <inertial pos="0.0354744 -0.000827888 0.0003809" quat="0.606373 0.417187 0.552395 0.391313" mass="0.0588507" diaginertia="1.28514e-05 1.22902e-05 5.9666e-06"/>
                            <joint name="g1-right_hand_index_0_joint" axis="0 0 1" range="0 1.5708" actuatorfrcrange="-1.4 1.4"/>
                            <geom class="g1-visual" mesh="g1-right_hand_index_0_link"/>
                            <geom class="g1-collision" mesh="g1-right_hand_index_0_link"/>
                            <body name="g1-right_hand_index_1_link" pos="0.0458 0 0">
                              <site name="g1-right_index" pos="0.04 0 0" size="0.01"/>
                              <inertial pos="0.0262819 -0.00171735 -0.000107789" quat="0.502861 0.502639 0.491799 0.502612" mass="0.0203063" diaginertia="4.61314e-06 3.86645e-06 1.53495e-06"/>
                              <joint name="g1-right_hand_index_1_joint" axis="0 0 1" range="0 1.74533" actuatorfrcrange="-1.4 1.4"/>
                              <geom class="g1-visual" mesh="g1-right_hand_index_1_link"/>
                              <geom class="g1-collision" mesh="g1-right_hand_index_1_link"/>
                            </body>
                          </body>
                        </body>
                      </body>
                    </body>
                  </body>
                </body>
              </body>
            </body>
          </body>
        </body>
      </body>
    </body>
    <body mocap="true" name="g1-mocap-left" pos="0.0633 0.2517 0.8813">
      <site name="g1-mocap-site-left" size=".02" type="sphere" rgba="0.13 0.3 0.2 1"/>
    </body>
    <body mocap="true" name="g1-mocap-right" pos="0.0195 -0.1102 0.909">
      <site name="g1-mocap-site-right" size=".03" type="sphere" rgba="0.13 0.3 0.2 1"/>
    </body>
    <body mocap="true" name="g1-mocap-right-foot" pos="-0.2738 -0.1662 0.1347">
      <site name="g1-mocap-site-right-foot" size=".02" type="sphere" rgba="0.13 0.3 0.2 1"/>
    </body>
    <body mocap="true" name="g1-mocap-left-foot" pos="-0.2237 0.3534 0.1347">
      <site name="g1-mocap-site-left-foot" size=".02" type="sphere" rgba="0.13 0.3 0.2 1"/>
    </body>
    <body mocap="true" name="g1-mocap-torso" pos="-0.15 0.1 1.0848">
      <site name="g1-mocap-site-torso" size=".02" type="sphere" rgba="0.13 0.3 0.2 1"/>
    </body>
  </worldbody>
  <actuator>
    <position class="g1-hip_pitch" name="g1-left_hip_pitch_joint" joint="g1-left_hip_pitch_joint"/>
    <position class="g1-hip_roll" name="g1-left_hip_roll_joint" joint="g1-left_hip_roll_joint"/>
    <position class="g1-hip_yaw" name="g1-left_hip_yaw_joint" joint="g1-left_hip_yaw_joint"/>
    <position class="g1-knee" name="g1-left_knee_joint" joint="g1-left_knee_joint"/>
    <position class="g1-ankle_pitch" name="g1-left_ankle_pitch_joint" joint="g1-left_ankle_pitch_joint"/>
    <position class="g1-ankle_roll" name="g1-left_ankle_roll_joint" joint="g1-left_ankle_roll_joint"/>
    <position class="g1-hip_pitch" name="g1-right_hip_pitch_joint" joint="g1-right_hip_pitch_joint"/>
    <position class="g1-hip_roll" name="g1-right_hip_roll_joint" joint="g1-right_hip_roll_joint"/>
    <position class="g1-hip_yaw" name="g1-right_hip_yaw_joint" joint="g1-right_hip_yaw_joint"/>
    <position class="g1-knee" name="g1-right_knee_joint" joint="g1-right_knee_joint"/>
    <position class="g1-ankle_pitch" name="g1-right_ankle_pitch_joint" joint="g1-right_ankle_pitch_joint"/>
    <position class="g1-ankle_roll" name="g1-right_ankle_roll_joint" joint="g1-right_ankle_roll_joint"/>
    <position class="g1-waist_yaw" name="g1-waist_yaw_joint" joint="g1-waist_yaw_joint"/>
    <position class="g1-waist_roll" name="g1-waist_roll_joint" joint="g1-waist_roll_joint"/>
    <position class="g1-waist_pitch" name="g1-waist_pitch_joint" joint="g1-waist_pitch_joint"/>
    <position class="g1-shoulder_pitch" name="g1-left_shoulder_pitch_joint" joint="g1-left_shoulder_pitch_joint"/>
    <position class="g1-shoulder_roll" name="g1-left_shoulder_roll_joint" joint="g1-left_shoulder_roll_joint"/>
    <position class="g1-shoulder_yaw" name="g1-left_shoulder_yaw_joint" joint="g1-left_shoulder_yaw_joint"/>
    <position class="g1-elbow" name="g1-left_elbow_joint" joint="g1-left_elbow_joint"/>
    <position class="g1-wrist_roll" name="g1-left_wrist_roll_joint" joint="g1-left_wrist_roll_joint"/>
    <position class="g1-wrist_pitch" name="g1-left_wrist_pitch_joint" joint="g1-left_wrist_pitch_joint"/>
    <position class="g1-wrist_yaw" name="g1-left_wrist_yaw_joint" joint="g1-left_wrist_yaw_joint"/>
    <position class="g1-shoulder_pitch" name="g1-right_shoulder_pitch_joint" joint="g1-right_shoulder_pitch_joint"/>
    <position class="g1-shoulder_roll" name="g1-right_shoulder_roll_joint" joint="g1-right_shoulder_roll_joint"/>
    <position class="g1-shoulder_yaw" name="g1-right_shoulder_yaw_joint" joint="g1-right_shoulder_yaw_joint"/>
    <position class="g1-elbow" name="g1-right_elbow_joint" joint="g1-right_elbow_joint"/>
    <position class="g1-wrist_roll" name="g1-right_wrist_roll_joint" joint="g1-right_wrist_roll_joint"/>
    <position class="g1-wrist_pitch" name="g1-right_wrist_pitch_joint" joint="g1-right_wrist_pitch_joint"/>
    <position class="g1-wrist_yaw" name="g1-right_wrist_yaw_joint" joint="g1-right_wrist_yaw_joint"/>
  </actuator>
  <sensor>
    <velocimeter site="g1-imu_in_torso" name="g1-local_linvel_torso"/>
    <velocimeter site="g1-imu_in_pelvis" name="g1-local_linvel_pelvis"/>
    <accelerometer site="g1-imu_in_torso" name="g1-accelerometer_torso"/>
    <accelerometer site="g1-imu_in_pelvis" name="g1-accelerometer_pelvis"/>
    <gyro site="g1-imu_in_torso" name="g1-gyro_torso"/>
    <gyro site="g1-imu_in_pelvis" name="g1-gyro_pelvis"/>
    <framezaxis objtype="site" objname="g1-imu_in_torso" name="g1-upvector_torso"/>
    <framezaxis objtype="site" objname="g1-imu_in_pelvis" name="g1-upvector_pelvis"/>
    <framequat objtype="site" objname="g1-imu_in_torso" name="g1-orientation_torso"/>
    <framequat objtype="site" objname="g1-imu_in_pelvis" name="g1-orientation_pelvis"/>
    <framelinvel objtype="site" objname="g1-imu_in_torso" name="g1-global_linvel_torso"/>
    <framelinvel objtype="site" objname="g1-imu_in_pelvis" name="g1-global_linvel_pelvis"/>
    <frameangvel objtype="site" objname="g1-imu_in_torso" name="g1-global_angvel_torso"/>
    <frameangvel objtype="site" objname="g1-imu_in_pelvis" name="g1-global_angvel_pelvis"/>
  </sensor>
  <equality>
    <weld site1="g1-left_palm" site2="g1-mocap-site-left"/>
    <weld site1="g1-right_palm" site2="g1-mocap-site-right"/>
    <weld site1="g1-right_foot" site2="g1-mocap-site-right-foot"/>
    <weld site1="g1-left_foot" site2="g1-mocap-site-left-foot"/>
    <weld site1="g1-imu_in_torso" site2="g1-mocap-site-torso"/>
  </equality>
</mujoco>