<?xml version="1.0" ?>
<mujoco>
  <default>
    <default class="xhand_left">
      <default class="xhand_left-motor">
        <joint/>
        <motor/>
      </default>
      <default class="xhand_left-visual">
        <geom material="xhand_left-visualgeom" contype="0" conaffinity="0" group="2"/>
      </default>
      <default class="xhand_left-collision">
        <geom material="xhand_left-collision_material" condim="3" contype="0" conaffinity="1" priority="1" group="1" solref="0.005 1" friction="1 0.01 0.01"/>
        <equality solimp="0.99 0.999 1e-05" solref="0.005 1"/>
      </default>
    </default>
  </default>
  <compiler angle="radian"/>
  <asset>
    <material name="xhand_left-RAL_9005_Jet_Black" rgba="0.055 0.055 0.063 1"/>
    <material name="xhand_left-RAL_9003_Signal_White" rgba="0.941 0.941 0.941 1"/>
    <material name="xhand_left-default_material" rgba="0.7 0.7 0.7 1"/>
    <material name="xhand_left-collision_material" rgba="1.0 0.28 0.1 0.9"/>
    <mesh name="xhand_left-left_hand_link.STL" file="./left_hand_link.STL"/>
    <mesh name="xhand_left-left_hand_ee_link.STL" file="./left_hand_ee_link.STL"/>
    <mesh name="xhand_left-left_hand_back_link.STL" file="./left_hand_back_link.STL"/>
    <mesh name="xhand_left-left_hand_thumb_bend_link.STL" file="./left_hand_thumb_bend_link.STL"/>
    <mesh name="xhand_left-left_hand_thumb_rota_link1.STL" file="./left_hand_thumb_rota_link1.STL"/>
    <mesh name="xhand_left-left_hand_thumb_rotaback_link1.STL" file="./left_hand_thumb_rotaback_link1.STL"/>
    <mesh name="xhand_left-left_hand_thumb_rota_link2.STL" file="./left_hand_thumb_rota_link2.STL"/>
    <mesh name="xhand_left-left_hand_thumb_rotaback_link2.STL" file="./left_hand_thumb_rotaback_link2.STL"/>
    <mesh name="xhand_left-left_hand_thumb_rota_tip.STL" file="./left_hand_thumb_rota_tip.STL"/>
    <mesh name="xhand_left-left_hand_index_bend_link.STL" file="./left_hand_index_bend_link.STL"/>
    <mesh name="xhand_left-left_hand_index_rota_link1.STL" file="./left_hand_index_rota_link1.STL"/>
    <mesh name="xhand_left-left_hand_index_rotaback_link1.STL" file="./left_hand_index_rotaback_link1.STL"/>
    <mesh name="xhand_left-left_hand_index_rota_link2.STL" file="./left_hand_index_rota_link2.STL"/>
    <mesh name="xhand_left-left_hand_index_rotaback_link2.STL" file="./left_hand_index_rotaback_link2.STL"/>
    <mesh name="xhand_left-left_hand_index_rota_tip.STL" file="./left_hand_index_rota_tip.STL"/>
    <mesh name="xhand_left-left_hand_mid_link1.STL" file="./left_hand_mid_link1.STL"/>
    <mesh name="xhand_left-left_hand_midback_link1.STL" file="./left_hand_midback_link1.STL"/>
    <mesh name="xhand_left-left_hand_mid_link2.STL" file="./left_hand_mid_link2.STL"/>
    <mesh name="xhand_left-left_hand_midback_link2.STL" file="./left_hand_midback_link2.STL"/>
    <mesh name="xhand_left-left_hand_mid_tip.STL" file="./left_hand_mid_tip.STL"/>
    <mesh name="xhand_left-left_hand_ring_link1.STL" file="./left_hand_ring_link1.STL"/>
    <mesh name="xhand_left-left_hand_ringback_link1.STL" file="./left_hand_ringback_link1.STL"/>
    <mesh name="xhand_left-left_hand_ring_link2.STL" file="./left_hand_ring_link2.STL"/>
    <mesh name="xhand_left-left_hand_ringback_link2.STL" file="./left_hand_ringback_link2.STL"/>
    <mesh name="xhand_left-left_hand_ring_tip.STL" file="./left_hand_ring_tip.STL"/>
    <mesh name="xhand_left-left_hand_pinky_link1.STL" file="./left_hand_pinky_link1.STL"/>
    <mesh name="xhand_left-left_hand_pinkyback_link1.STL" file="./left_hand_pinkyback_link1.STL"/>
    <mesh name="xhand_left-left_hand_pinky_link2.STL" file="./left_hand_pinky_link2.STL"/>
    <mesh name="xhand_left-left_hand_pinkyback_link2.STL" file="./left_hand_pinkyback_link2.STL"/>
    <mesh name="xhand_left-left_hand_pinky_tip.STL" file="./left_hand_pinky_tip.STL"/>
  </asset>
  <worldbody>
    <body name="xhand_left" childclass="xhand_left" pos="0 0 0.20624829" quat="0.7071 0.7071 0 0">
      <joint name="xhand_left-floating_base"/>
      <geom name="xhand_left-left_hand_link_collision" pos="0 0 0" quat="1.0 0.0 0.0 0.0" type="mesh" mesh="xhand_left-left_hand_link.STL" class="xhand_left-collision"/>
      <geom name="xhand_left-left_hand_link_visual" pos="0 0 0" quat="1.0 0.0 0.0 0.0" material="xhand_left-RAL_9005_Jet_Black" type="mesh" mesh="xhand_left-left_hand_link.STL" class="xhand_left-visual"/>
      <body name="xhand_left-left_hand_ee_link" pos="0 0 -0.065" quat="1.0 0.0 0.0 0.0">
        <inertial pos="-9.14235300816632E-20 6.87814821208628E-18 0" quat="1.0 0.0 0.0 0.0" mass="0.00000565" diaginertia="1e-11 1e-11 1e-11"/>
        <geom name="xhand_left-left_hand_ee_link_collision" pos="0 0 0" quat="1.0 0.0 0.0 0.0" type="mesh" mesh="xhand_left-left_hand_ee_link.STL" class="xhand_left-collision"/>
        <geom name="xhand_left-left_hand_ee_link_visual" pos="0 0 0" quat="1.0 0.0 0.0 0.0" material="xhand_left-RAL_9005_Jet_Black" type="mesh" mesh="xhand_left-left_hand_ee_link.STL" class="xhand_left-visual"/>
      </body>
      <body name="xhand_left-left_hand_back_link" pos="0 0 -0.065" quat="1.0 0.0 0.0 0.0">
        <inertial pos="-0.00206614328070064 0.0140092020913419 0.000644119291874204" quat="1.0 0.0 0.0 0.0" mass="0.00000020" diaginertia="1e-11 1e-11 1e-11"/>
        <geom name="xhand_left-left_hand_back_link_collision" pos="0 0 0" quat="1.0 0.0 0.0 0.0" type="mesh" mesh="xhand_left-left_hand_back_link.STL" class="xhand_left-collision"/>
        <geom name="xhand_left-left_hand_back_link_visual" pos="0 0 0" quat="1.0 0.0 0.0 0.0" material="xhand_left-RAL_9003_Signal_White" type="mesh" mesh="xhand_left-left_hand_back_link.STL" class="xhand_left-visual"/>
      </body>
      <body name="xhand_left-left_hand_thumb_bend_link" pos="0.0228 -0.0095 -0.0305" quat="1.0 0.0 0.0 0.0">
        <joint name="xhand_left-left_hand_thumb_bend_joint" type="hinge" ref="0.0" class="xhand_left-motor" range="0 1.832" axis="0 0 -1"/>
        <inertial pos="0.0144315029292586 0.00116653625408803 -6.50665966587562E-05" quat="1.0 0.0 0.0 0.0" mass="0.0118729" diaginertia="6.2e-07 1.6e-06 1.62e-06"/>
        <geom name="xhand_left-left_hand_thumb_bend_link_collision" pos="0 0 0" quat="1.0 0.0 0.0 0.0" type="mesh" mesh="xhand_left-left_hand_thumb_bend_link.STL" class="xhand_left-collision"/>
        <geom name="xhand_left-left_hand_thumb_bend_link_visual" pos="0 0 0" quat="1.0 0.0 0.0 0.0" material="xhand_left-RAL_9005_Jet_Black" type="mesh" mesh="xhand_left-left_hand_thumb_bend_link.STL" class="xhand_left-visual"/>
        <body name="xhand_left-left_hand_thumb_rota_link1" pos="0.028599 -0.0083177 0.00178" quat="0.991239538700108 -0.1304994696550749 0.0026560308583164923 -0.020174509595553045">
          <joint name="xhand_left-left_hand_thumb_rota_joint1" type="hinge" ref="0.0" class="xhand_left-motor" range="-0.698 1.745" axis="0 1 0"/>
          <inertial pos="0.028699400584835 0.000353013004294657 -0.0013521057380018" quat="1.0 0.0 0.0 0.0" mass="0.13268494" diaginertia="1.702e-05 3.592e-05 4.285e-05"/>
          <geom name="xhand_left-left_hand_thumb_rota_link1_collision" pos="0 0 0" quat="1.0 0.0 0.0 0.0" type="mesh" mesh="xhand_left-left_hand_thumb_rota_link1.STL" class="xhand_left-collision"/>
          <geom name="xhand_left-left_hand_thumb_rota_link1_visual" pos="0 0 0" quat="1.0 0.0 0.0 0.0" material="xhand_left-RAL_9005_Jet_Black" type="mesh" mesh="xhand_left-left_hand_thumb_rota_link1.STL" class="xhand_left-visual"/>
          <body name="xhand_left-left_hand_thumb_rotaback_link1" pos="0.0553000000000004 0 0" quat="1.0 0.0 0.0 0.0">
            <inertial pos="-0.0296284435379629 -0.00145635345487384 0.00757347054072984" quat="1.0 0.0 0.0 0.0" mass="0.00000006" diaginertia="1e-11 1e-11 1e-11"/>
            <geom name="xhand_left-left_hand_thumb_rotaback_link1_collision" pos="0 0 0" quat="1.0 0.0 0.0 0.0" type="mesh" mesh="xhand_left-left_hand_thumb_rotaback_link1.STL" class="xhand_left-collision"/>
            <geom name="xhand_left-left_hand_thumb_rotaback_link1_visual" pos="0 0 0" quat="1.0 0.0 0.0 0.0" material="xhand_left-RAL_9003_Signal_White" type="mesh" mesh="xhand_left-left_hand_thumb_rotaback_link1.STL" class="xhand_left-visual"/>
          </body>
          <body name="xhand_left-left_hand_thumb_rota_link2" pos="0.0553 0 0" quat="1.0 0.0 0.0 0.0">
            <joint name="xhand_left-left_hand_thumb_rota_joint2" type="hinge" ref="0.0" class="xhand_left-motor" range="0 1.745" axis="0 1 0"/>
            <inertial pos="0.0228414266462457 0.000460794125797265 -0.000578251645405752" quat="1.0 0.0 0.0 0.0" mass="0.03536566" diaginertia="3.53e-06 7.85e-06 8.98e-06"/>
            <geom name="xhand_left-left_hand_thumb_rota_link2_collision" pos="0 0 0" quat="1.0 0.0 0.0 0.0" type="mesh" mesh="xhand_left-left_hand_thumb_rota_link2.STL" class="xhand_left-collision"/>
            <geom name="xhand_left-left_hand_thumb_rota_link2_visual" pos="0 0 0" quat="1.0 0.0 0.0 0.0" material="xhand_left-RAL_9005_Jet_Black" type="mesh" mesh="xhand_left-left_hand_thumb_rota_link2.STL" class="xhand_left-visual"/>
            <body name="xhand_left-left_hand_thumb_rotaback_link2" pos="0.0499881470979494 0 0" quat="1.0 0.0 0.0 0.0">
              <inertial pos="-0.0256682291910944 0.000513274886833534 0.00926148645051527" quat="1.0 0.0 0.0 0.0" mass="0.00000004" diaginertia="1e-11 1e-11 1e-11"/>
              <geom name="xhand_left-left_hand_thumb_rotaback_link2_collision" pos="0 0 0" quat="1.0 0.0 0.0 0.0" type="mesh" mesh="xhand_left-left_hand_thumb_rotaback_link2.STL" class="xhand_left-collision"/>
              <geom name="xhand_left-left_hand_thumb_rotaback_link2_visual" pos="0 0 0" quat="1.0 0.0 0.0 0.0" material="xhand_left-RAL_9003_Signal_White" type="mesh" mesh="xhand_left-left_hand_thumb_rotaback_link2.STL" class="xhand_left-visual"/>
            </body>
            <body name="xhand_left-left_hand_thumb_rota_tip" pos="0.0499881470979494 0 0" quat="1.0 0.0 0.0 0.0">
              <inertial pos="-8.32667268468867E-17 1.04083408558608E-17 2.28983498828939E-16" quat="1.0 0.0 0.0 0.0" mass="0.00000565" diaginertia="1e-11 1e-11 1e-11"/>
              <geom name="xhand_left-left_hand_thumb_rota_tip_collision" pos="0 0 0" quat="1.0 0.0 0.0 0.0" type="mesh" mesh="xhand_left-left_hand_thumb_rota_tip.STL" class="xhand_left-collision"/>
              <geom name="xhand_left-left_hand_thumb_rota_tip_visual" pos="0 0 0" quat="1.0 0.0 0.0 0.0" material="xhand_left-RAL_9005_Jet_Black" type="mesh" mesh="xhand_left-left_hand_thumb_rota_tip.STL" class="xhand_left-visual"/>
            </body>
          </body>
        </body>
      </body>
      <body name="xhand_left-left_hand_index_bend_link" pos="0.0265 -0.0065 -0.0899" quat="1.0 0.0 0.0 0.0">
        <joint name="xhand_left-left_hand_index_bend_joint" type="hinge" ref="0.0" class="xhand_left-motor" range="-0.174 0.174" axis="0 -1 0"/>
        <inertial pos="-0.000388464456994867 0.000992075604557427 -0.00970333167554097" quat="1.0 0.0 0.0 0.0" mass="0.06910833" diaginertia="1.74e-05 1.677e-05 3.45e-06"/>
        <geom name="xhand_left-left_hand_index_bend_link_visual" pos="0 0 0" quat="1.0 0.0 0.0 0.0" material="xhand_left-RAL_9005_Jet_Black" type="mesh" mesh="xhand_left-left_hand_index_bend_link.STL" class="xhand_left-visual"/>
        <body name="xhand_left-left_hand_index_rota_link1" pos="0 0 -0.0178" quat="1.0 0.0 0.0 0.0">
          <joint name="xhand_left-left_hand_index_joint1" type="hinge" ref="0.0" class="xhand_left-motor" range="0 1.919" axis="-1 0 0"/>
          <inertial pos="-3.58049083604185E-05 -0.00053041759210529 -0.0332784671157223" quat="1.0 0.0 0.0 0.0" mass="0.06298297" diaginertia="1.738e-05 1.686e-05 3.2e-06"/>
          <geom name="xhand_left-left_hand_index_rota_link1_collision" pos="0 0 0" quat="1.0 0.0 0.0 0.0" type="mesh" mesh="xhand_left-left_hand_index_rota_link1.STL" class="xhand_left-collision"/>
          <geom name="xhand_left-left_hand_index_rota_link1_visual" pos="0 0 0" quat="1.0 0.0 0.0 0.0" material="xhand_left-RAL_9005_Jet_Black" type="mesh" mesh="xhand_left-left_hand_index_rota_link1.STL" class="xhand_left-visual"/>
          <body name="xhand_left-left_hand_index_rotaback_link1" pos="0 0 -0.0558000000000001" quat="1.0 0.0 0.0 0.0">
            <inertial pos="0.00014803463945353 0.0115948039961551 0.0241234085631844" quat="1.0 0.0 0.0 0.0" mass="0.00000002" diaginertia="1e-11 1e-11 1e-11"/>
            <geom name="xhand_left-left_hand_index_rotaback_link1_collision" pos="0 0 0" quat="1.0 0.0 0.0 0.0" type="mesh" mesh="xhand_left-left_hand_index_rotaback_link1.STL" class="xhand_left-collision"/>
            <geom name="xhand_left-left_hand_index_rotaback_link1_visual" pos="0 0 0" quat="1.0 0.0 0.0 0.0" material="xhand_left-RAL_9003_Signal_White" type="mesh" mesh="xhand_left-left_hand_index_rotaback_link1.STL" class="xhand_left-visual"/>
          </body>
          <body name="xhand_left-left_hand_index_rota_link2" pos="0 0 -0.0558" quat="1.0 0.0 0.0 0.0">
            <joint name="xhand_left-left_hand_index_joint2" type="hinge" ref="0.0" class="xhand_left-motor" range="0 1.919" axis="-1 0 0"/>
            <inertial pos="0.000248361662016118 -0.00119905190206697 -0.0213789854478661" quat="1.0 0.0 0.0 0.0" mass="0.01588724" diaginertia="2.77e-06 2.83e-06 8.5e-07"/>
            <geom name="xhand_left-left_hand_index_rota_link2_collision" pos="0 0 0" quat="1.0 0.0 0.0 0.0" type="mesh" mesh="xhand_left-left_hand_index_rota_link2.STL" class="xhand_left-collision"/>
            <geom name="xhand_left-left_hand_index_rota_link2_visual" pos="0 0 0" quat="1.0 0.0 0.0 0.0" material="xhand_left-RAL_9005_Jet_Black" type="mesh" mesh="xhand_left-left_hand_index_rota_link2.STL" class="xhand_left-visual"/>
            <body name="xhand_left-left_hand_index_rotaback_link2" pos="0 0 -0.0422482924089404" quat="1.0 0.0 0.0 0.0">
              <inertial pos="-0.000157950438605944 0.00758843721876324 0.017665521085575" quat="1.0 0.0 0.0 0.0" mass="0.00000001" diaginertia="1e-11 1e-11 1e-11"/>
              <geom name="xhand_left-left_hand_index_rotaback_link2_collision" pos="0 0 0" quat="1.0 0.0 0.0 0.0" type="mesh" mesh="xhand_left-left_hand_index_rotaback_link2.STL" class="xhand_left-collision"/>
              <geom name="xhand_left-left_hand_index_rotaback_link2_visual" pos="0 0 0" quat="1.0 0.0 0.0 0.0" material="xhand_left-RAL_9003_Signal_White" type="mesh" mesh="xhand_left-left_hand_index_rotaback_link2.STL" class="xhand_left-visual"/>
            </body>
            <body name="xhand_left-left_hand_index_rota_tip" pos="0 0 -0.0422482924089404" quat="1.0 0.0 0.0 0.0">
              <inertial pos="-1.00613961606655E-16 1.90819582357449E-17 0" quat="1.0 0.0 0.0 0.0" mass="0.00000565" diaginertia="1e-11 1e-11 1e-11"/>
              <geom name="xhand_left-left_hand_index_rota_tip_collision" pos="0 0 0" quat="1.0 0.0 0.0 0.0" type="mesh" mesh="xhand_left-left_hand_index_rota_tip.STL" class="xhand_left-collision"/>
              <geom name="xhand_left-left_hand_index_rota_tip_visual" pos="0 0 0" quat="1.0 0.0 0.0 0.0" material="xhand_left-RAL_9005_Jet_Black" type="mesh" mesh="xhand_left-left_hand_index_rota_tip.STL" class="xhand_left-visual"/>
            </body>
          </body>
        </body>
      </body>
      <body name="xhand_left-left_hand_mid_link1" pos="0.004 -0.0065 -0.1082" quat="1.0 0.0 0.0 0.0">
        <joint name="xhand_left-left_hand_mid_joint1" type="hinge" ref="0.0" class="xhand_left-motor" range="0 1.919" axis="-1 0 0"/>
        <inertial pos="-3.58049083603916E-05 -0.000530417592105155 -0.0332784671157224" quat="1.0 0.0 0.0 0.0" mass="0.06298297" diaginertia="1.738e-05 1.686e-05 3.2e-06"/>
        <geom name="xhand_left-left_hand_mid_link1_collision" pos="0 0 0" quat="1.0 0.0 0.0 0.0" type="mesh" mesh="xhand_left-left_hand_mid_link1.STL" class="xhand_left-collision"/>
        <geom name="xhand_left-left_hand_mid_link1_visual" pos="0 0 0" quat="1.0 0.0 0.0 0.0" material="xhand_left-RAL_9005_Jet_Black" type="mesh" mesh="xhand_left-left_hand_mid_link1.STL" class="xhand_left-visual"/>
        <body name="xhand_left-left_hand_midback_link1" pos="0 0 -0.0558000000000001" quat="1.0 0.0 0.0 0.0">
          <inertial pos="0.000148034858018445 0.0115948038778314 0.024123407735519" quat="1.0 0.0 0.0 0.0" mass="0.00000002" diaginertia="1e-11 1e-11 1e-11"/>
          <geom name="xhand_left-left_hand_midback_link1_collision" pos="0 0 0" quat="1.0 0.0 0.0 0.0" type="mesh" mesh="xhand_left-left_hand_midback_link1.STL" class="xhand_left-collision"/>
          <geom name="xhand_left-left_hand_midback_link1_visual" pos="0 0 0" quat="1.0 0.0 0.0 0.0" material="xhand_left-RAL_9003_Signal_White" type="mesh" mesh="xhand_left-left_hand_midback_link1.STL" class="xhand_left-visual"/>
        </body>
        <body name="xhand_left-left_hand_mid_link2" pos="0 0 -0.0558" quat="1.0 0.0 0.0 0.0">
          <joint name="xhand_left-left_hand_mid_joint2" type="hinge" ref="0.0" class="xhand_left-motor" range="0 1.919" axis="-1 0 0"/>
          <inertial pos="0.000248361662016048 -0.00119905190206678 -0.0213789854478656" quat="1.0 0.0 0.0 0.0" mass="0.01588724" diaginertia="2.77e-06 2.83e-06 8.5e-07"/>
          <geom name="xhand_left-left_hand_mid_link2_collision" pos="0 0 0" quat="1.0 0.0 0.0 0.0" type="mesh" mesh="xhand_left-left_hand_mid_link2.STL" class="xhand_left-collision"/>
          <geom name="xhand_left-left_hand_mid_link2_visual" pos="0 0 0" quat="1.0 0.0 0.0 0.0" material="xhand_left-RAL_9005_Jet_Black" type="mesh" mesh="xhand_left-left_hand_mid_link2.STL" class="xhand_left-visual"/>
          <body name="xhand_left-left_hand_midback_link2" pos="0 0 -0.0422482924089403" quat="1.0 0.0 0.0 0.0">
            <inertial pos="-0.000157950438634382 0.00758843721877263 0.0176655210856587" quat="1.0 0.0 0.0 0.0" mass="0.00000001" diaginertia="1e-11 1e-11 1e-11"/>
            <geom name="xhand_left-left_hand_midback_link2_collision" pos="0 0 0" quat="1.0 0.0 0.0 0.0" type="mesh" mesh="xhand_left-left_hand_midback_link2.STL" class="xhand_left-collision"/>
            <geom name="xhand_left-left_hand_midback_link2_visual" pos="0 0 0" quat="1.0 0.0 0.0 0.0" material="xhand_left-RAL_9003_Signal_White" type="mesh" mesh="xhand_left-left_hand_midback_link2.STL" class="xhand_left-visual"/>
          </body>
          <body name="xhand_left-left_hand_mid_tip" pos="0 0 -0.0422482924089403" quat="1.0 0.0 0.0 0.0">
            <inertial pos="-1.90819582357449E-17 1.55257751099924E-16 0" quat="1.0 0.0 0.0 0.0" mass="0.00000565" diaginertia="1e-11 1e-11 1e-11"/>
            <geom name="xhand_left-left_hand_mid_tip_collision" pos="0 0 0" quat="1.0 0.0 0.0 0.0" type="mesh" mesh="xhand_left-left_hand_mid_tip.STL" class="xhand_left-collision"/>
            <geom name="xhand_left-left_hand_mid_tip_visual" pos="0 0 0" quat="1.0 0.0 0.0 0.0" material="xhand_left-RAL_9005_Jet_Black" type="mesh" mesh="xhand_left-left_hand_mid_tip.STL" class="xhand_left-visual"/>
          </body>
        </body>
      </body>
      <body name="xhand_left-left_hand_ring_link1" pos="-0.016 -0.0065 -0.1052" quat="1.0 0.0 0.0 0.0">
        <joint name="xhand_left-left_hand_ring_joint1" type="hinge" ref="0.0" class="xhand_left-motor" range="0 1.919" axis="-1 0 0"/>
        <inertial pos="-3.58049083603491E-05 -0.000530417592105894 -0.0332784671157224" quat="1.0 0.0 0.0 0.0" mass="0.06298297" diaginertia="1.738e-05 1.686e-05 3.2e-06"/>
        <geom name="xhand_left-left_hand_ring_link1_collision" pos="0 0 0" quat="1.0 0.0 0.0 0.0" type="mesh" mesh="xhand_left-left_hand_ring_link1.STL" class="xhand_left-collision"/>
        <geom name="xhand_left-left_hand_ring_link1_visual" pos="0 0 0" quat="1.0 0.0 0.0 0.0" material="xhand_left-RAL_9005_Jet_Black" type="mesh" mesh="xhand_left-left_hand_ring_link1.STL" class="xhand_left-visual"/>
        <body name="xhand_left-left_hand_ringback_link1" pos="0 0 -0.0558000000000001" quat="1.0 0.0 0.0 0.0">
          <inertial pos="0.000148033930314071 0.0115948038916307 0.0241234089720673" quat="1.0 0.0 0.0 0.0" mass="0.00000002" diaginertia="1e-11 1e-11 1e-11"/>
          <geom name="xhand_left-left_hand_ringback_link1_collision" pos="0 0 0" quat="1.0 0.0 0.0 0.0" type="mesh" mesh="xhand_left-left_hand_ringback_link1.STL" class="xhand_left-collision"/>
          <geom name="xhand_left-left_hand_ringback_link1_visual" pos="0 0 0" quat="1.0 0.0 0.0 0.0" material="xhand_left-RAL_9003_Signal_White" type="mesh" mesh="xhand_left-left_hand_ringback_link1.STL" class="xhand_left-visual"/>
        </body>
        <body name="xhand_left-left_hand_ring_link2" pos="0 0 -0.0558" quat="1.0 0.0 0.0 0.0">
          <joint name="xhand_left-left_hand_ring_joint2" type="hinge" ref="0.0" class="xhand_left-motor" range="0 1.919" axis="-1 0 0"/>
          <inertial pos="0.000248361662016028 -0.0011990519020675 -0.0213789854478657" quat="1.0 0.0 0.0 0.0" mass="0.01588724" diaginertia="2.77e-06 2.83e-06 8.5e-07"/>
          <geom name="xhand_left-left_hand_ring_link2_collision" pos="0 0 0" quat="1.0 0.0 0.0 0.0" type="mesh" mesh="xhand_left-left_hand_ring_link2.STL" class="xhand_left-collision"/>
          <geom name="xhand_left-left_hand_ring_link2_visual" pos="0 0 0" quat="1.0 0.0 0.0 0.0" material="xhand_left-RAL_9005_Jet_Black" type="mesh" mesh="xhand_left-left_hand_ring_link2.STL" class="xhand_left-visual"/>
          <body name="xhand_left-left_hand_ringback_link2" pos="0 0 -0.0422482924089404" quat="1.0 0.0 0.0 0.0">
            <inertial pos="-0.000157950438606443 0.00758843721877125 0.0176655210856417" quat="1.0 0.0 0.0 0.0" mass="0.00000001" diaginertia="1e-11 1e-11 1e-11"/>
            <geom name="xhand_left-left_hand_ringback_link2_collision" pos="0 0 0" quat="1.0 0.0 0.0 0.0" type="mesh" mesh="xhand_left-left_hand_ringback_link2.STL" class="xhand_left-collision"/>
            <geom name="xhand_left-left_hand_ringback_link2_visual" pos="0 0 0" quat="1.0 0.0 0.0 0.0" material="xhand_left-RAL_9003_Signal_White" type="mesh" mesh="xhand_left-left_hand_ringback_link2.STL" class="xhand_left-visual"/>
          </body>
          <body name="xhand_left-left_hand_ring_tip" pos="0 0 -0.0422482924089404" quat="1.0 0.0 0.0 0.0">
            <inertial pos="-4.85722573273506E-17 -5.31692745386891E-16 0" quat="1.0 0.0 0.0 0.0" mass="0.00000565" diaginertia="1e-11 1e-11 1e-11"/>
            <geom name="xhand_left-left_hand_ring_tip_collision" pos="0 0 0" quat="1.0 0.0 0.0 0.0" type="mesh" mesh="xhand_left-left_hand_ring_tip.STL" class="xhand_left-collision"/>
            <geom name="xhand_left-left_hand_ring_tip_visual" pos="0 0 0" quat="1.0 0.0 0.0 0.0" material="xhand_left-RAL_9005_Jet_Black" type="mesh" mesh="xhand_left-left_hand_ring_tip.STL" class="xhand_left-visual"/>
          </body>
        </body>
      </body>
      <body name="xhand_left-left_hand_pinky_link1" pos="-0.036 -0.0065 -0.1022" quat="1.0 0.0 0.0 0.0">
        <joint name="xhand_left-left_hand_pinky_joint1" type="hinge" ref="0.0" class="xhand_left-motor" range="0 1.919" axis="-1 0 0"/>
        <inertial pos="-3.58049083603318E-05 -0.000530417592106195 -0.0332784671157224" quat="1.0 0.0 0.0 0.0" mass="0.06298297" diaginertia="1.738e-05 1.686e-05 3.2e-06"/>
        <geom name="xhand_left-left_hand_pinky_link1_collision" pos="0 0 0" quat="1.0 0.0 0.0 0.0" type="mesh" mesh="xhand_left-left_hand_pinky_link1.STL" class="xhand_left-collision"/>
        <geom name="xhand_left-left_hand_pinky_link1_visual" pos="0 0 0" quat="1.0 0.0 0.0 0.0" material="xhand_left-RAL_9005_Jet_Black" type="mesh" mesh="xhand_left-left_hand_pinky_link1.STL" class="xhand_left-visual"/>
        <body name="xhand_left-left_hand_pinkyback_link1" pos="0 0 -0.0558000000000001" quat="1.0 0.0 0.0 0.0">
          <inertial pos="0.000148034877008783 0.0115948040346325 0.024123408080182" quat="1.0 0.0 0.0 0.0" mass="0.00000002" diaginertia="1e-11 1e-11 1e-11"/>
          <geom name="xhand_left-left_hand_pinkyback_link1_collision" pos="0 0 0" quat="1.0 0.0 0.0 0.0" type="mesh" mesh="xhand_left-left_hand_pinkyback_link1.STL" class="xhand_left-collision"/>
          <geom name="xhand_left-left_hand_pinkyback_link1_visual" pos="0 0 0" quat="1.0 0.0 0.0 0.0" material="xhand_left-RAL_9003_Signal_White" type="mesh" mesh="xhand_left-left_hand_pinkyback_link1.STL" class="xhand_left-visual"/>
        </body>
        <body name="xhand_left-left_hand_pinky_link2" pos="0 0 -0.0558" quat="1.0 0.0 0.0 0.0">
          <joint name="xhand_left-left_hand_pinky_joint2" type="hinge" ref="0.0" class="xhand_left-motor" range="0 1.919" axis="-1 0 0"/>
          <inertial pos="0.000248361696242753 -0.00119905185762272 -0.0213789857007834" quat="1.0 0.0 0.0 0.0" mass="0.01588724" diaginertia="2.77e-06 2.83e-06 8.5e-07"/>
          <geom name="xhand_left-left_hand_pinky_link2_collision" pos="0 0 0" quat="1.0 0.0 0.0 0.0" type="mesh" mesh="xhand_left-left_hand_pinky_link2.STL" class="xhand_left-collision"/>
          <geom name="xhand_left-left_hand_pinky_link2_visual" pos="0 0 0" quat="1.0 0.0 0.0 0.0" material="xhand_left-RAL_9005_Jet_Black" type="mesh" mesh="xhand_left-left_hand_pinky_link2.STL" class="xhand_left-visual"/>
          <body name="xhand_left-left_hand_pinkyback_link2" pos="0 0 -0.0422482924089405" quat="1.0 0.0 0.0 0.0">
            <inertial pos="-0.0001579504385983 0.00758843721876557 0.0176655210856048" quat="1.0 0.0 0.0 0.0" mass="0.00000001" diaginertia="1e-11 1e-11 1e-11"/>
            <geom name="xhand_left-left_hand_pinkyback_link2_collision" pos="0 0 0" quat="1.0 0.0 0.0 0.0" type="mesh" mesh="xhand_left-left_hand_pinkyback_link2.STL" class="xhand_left-collision"/>
            <geom name="xhand_left-left_hand_pinkyback_link2_visual" pos="0 0 0" quat="1.0 0.0 0.0 0.0" material="xhand_left-RAL_9003_Signal_White" type="mesh" mesh="xhand_left-left_hand_pinkyback_link2.STL" class="xhand_left-visual"/>
          </body>
          <body name="xhand_left-left_hand_pinky_tip" pos="0 0 -0.0422482924089405" quat="1.0 0.0 0.0 0.0">
            <inertial pos="1.38777878078145E-17 -8.84708972748172E-16 2.77555756156289E-17" quat="1.0 0.0 0.0 0.0" mass="0.00000565" diaginertia="1e-11 1e-11 1e-11"/>
            <geom name="xhand_left-left_hand_pinky_tip_collision" pos="0 0 0" quat="1.0 0.0 0.0 0.0" type="mesh" mesh="xhand_left-left_hand_pinky_tip.STL" class="xhand_left-collision"/>
            <geom name="xhand_left-left_hand_pinky_tip_visual" pos="0 0 0" quat="1.0 0.0 0.0 0.0" material="xhand_left-RAL_9005_Jet_Black" type="mesh" mesh="xhand_left-left_hand_pinky_tip.STL" class="xhand_left-visual"/>
          </body>
        </body>
      </body>
      <site name="xhand_left-left_hand_link_site" pos="0 0 0" quat="1 0 0 0"/>
      <camera name="xhand_left-front_camera" mode="track" fovy="90.0" quat="4.329780281177467e-17 4.329780281177466e-17 0.7071067811865475 0.7071067811865476" pos="0.0 2.0 0.5"/>
      <camera name="xhand_left-side_camera" mode="track" fovy="90.0" quat="-0.5 -0.4999999999999999 0.5 0.5000000000000001" pos="-2.0 0.0 0.5"/>
    </body>
    <body mocap="true" name="xhand_left-left-wrist" pos="0.0 0.0 0.20624829" quat="0 -0.7071 -0.7071 0">
      <site pos="0 0 0" name="xhand_left-left-wrist-site-mocap" rgba="0.658 0.411 0.75 1" size=".01" type="sphere"/>
    </body>
    <body mocap="true" name="xhand_left-left-index-finger-tip" pos="0.0265 0.20574829 0.19974829" quat="0 -0.7071 -0.7071 0">
      <site pos="0 0 0" name="xhand_left-left-index-finger-tip-site-mocap" rgba="0.658 0.411 0.75 1" size=".01" type="sphere"/>
    </body>
    <body mocap="true" name="xhand_left-left-middle-finger-tip" pos="0.004 0.20624829 0.19974829" quat="0 -0.7071 -0.7071 0">
      <site pos="0 0 0" name="xhand_left-left-middle-finger-tip-site-mocap" rgba="0.658 0.411 0.75 1" size=".01" type="sphere"/>
    </body>
    <body mocap="true" name="xhand_left-left-ring-finger-tip" pos="-0.016 0.20324829 0.19974829" quat="0 -0.7071 -0.7071 0">
      <site pos="0 0 0" name="xhand_left-left-ring-finger-tip-site-mocap" rgba="0.658 0.411 0.75 1" size=".01" type="sphere"/>
    </body>
    <body mocap="true" name="xhand_left-left-pinky-finger-tip" pos="-0.036 0.20024829 0.19974829" quat="0 -0.7071 -0.7071 0">
      <site pos="0 0 0" name="xhand_left-left-pinky-finger-tip-site-mocap" rgba="0.658 0.411 0.75 1" size=".01" type="sphere"/>
    </body>
    <body mocap="true" name="xhand_left-left-thumb-tip" pos="0.152 0.02872 0.18843059" quat="0.6533 -0.2706 -0.6533 -0.2706">
      <site name="xhand_left-left-thumb-tip-site-mocap" rgba="0.658 0.411 0.75 1" size=".01" type="sphere"/>
    </body>
  </worldbody>
  <actuator>
    <motor name="xhand_left-left_hand_thumb_bend_joint_ctrl" joint="xhand_left-left_hand_thumb_bend_joint" class="xhand_left-motor"/>
    <motor name="xhand_left-left_hand_thumb_rota_joint1_ctrl" joint="xhand_left-left_hand_thumb_rota_joint1" class="xhand_left-motor"/>
    <motor name="xhand_left-left_hand_thumb_rota_joint2_ctrl" joint="xhand_left-left_hand_thumb_rota_joint2" class="xhand_left-motor"/>
    <motor name="xhand_left-left_hand_index_bend_joint_ctrl" joint="xhand_left-left_hand_index_bend_joint" class="xhand_left-motor"/>
    <motor name="xhand_left-left_hand_index_joint1_ctrl" joint="xhand_left-left_hand_index_joint1" class="xhand_left-motor"/>
    <motor name="xhand_left-left_hand_index_joint2_ctrl" joint="xhand_left-left_hand_index_joint2" class="xhand_left-motor"/>
    <motor name="xhand_left-left_hand_mid_joint1_ctrl" joint="xhand_left-left_hand_mid_joint1" class="xhand_left-motor"/>
    <motor name="xhand_left-left_hand_mid_joint2_ctrl" joint="xhand_left-left_hand_mid_joint2" class="xhand_left-motor"/>
    <motor name="xhand_left-left_hand_ring_joint1_ctrl" joint="xhand_left-left_hand_ring_joint1" class="xhand_left-motor"/>
    <motor name="xhand_left-left_hand_ring_joint2_ctrl" joint="xhand_left-left_hand_ring_joint2" class="xhand_left-motor"/>
    <motor name="xhand_left-left_hand_pinky_joint1_ctrl" joint="xhand_left-left_hand_pinky_joint1" class="xhand_left-motor"/>
    <motor name="xhand_left-left_hand_pinky_joint2_ctrl" joint="xhand_left-left_hand_pinky_joint2" class="xhand_left-motor"/>
  </actuator>
  <contact>
    <exclude body1="xhand_left" body2="xhand_left-left_hand_ee_link"/>
    <exclude body1="xhand_left" body2="xhand_left-left_hand_back_link"/>
    <exclude body1="xhand_left" body2="xhand_left-left_hand_thumb_bend_link"/>
    <exclude body1="xhand_left-left_hand_thumb_bend_link" body2="xhand_left-left_hand_thumb_rota_link1"/>
    <exclude body1="xhand_left-left_hand_thumb_rota_link1" body2="xhand_left-left_hand_thumb_rotaback_link1"/>
    <exclude body1="xhand_left-left_hand_thumb_rota_link1" body2="xhand_left-left_hand_thumb_rota_link2"/>
    <exclude body1="xhand_left-left_hand_thumb_rota_link2" body2="xhand_left-left_hand_thumb_rotaback_link2"/>
    <exclude body1="xhand_left-left_hand_thumb_rota_link2" body2="xhand_left-left_hand_thumb_rota_tip"/>
    <exclude body1="xhand_left-left_hand_index_rota_link1" body2="xhand_left-left_hand_index_rotaback_link1"/>
    <exclude body1="xhand_left-left_hand_index_rota_link1" body2="xhand_left-left_hand_index_rota_link2"/>
    <exclude body1="xhand_left-left_hand_index_rota_link2" body2="xhand_left-left_hand_index_rotaback_link2"/>
    <exclude body1="xhand_left-left_hand_index_rota_link2" body2="xhand_left-left_hand_index_rota_tip"/>
    <exclude body1="xhand_left" body2="xhand_left-left_hand_mid_link1"/>
    <exclude body1="xhand_left-left_hand_mid_link1" body2="xhand_left-left_hand_midback_link1"/>
    <exclude body1="xhand_left-left_hand_mid_link1" body2="xhand_left-left_hand_mid_link2"/>
    <exclude body1="xhand_left-left_hand_mid_link2" body2="xhand_left-left_hand_midback_link2"/>
    <exclude body1="xhand_left-left_hand_mid_link2" body2="xhand_left-left_hand_mid_tip"/>
    <exclude body1="xhand_left" body2="xhand_left-left_hand_ring_link1"/>
    <exclude body1="xhand_left-left_hand_ring_link1" body2="xhand_left-left_hand_ringback_link1"/>
    <exclude body1="xhand_left-left_hand_ring_link1" body2="xhand_left-left_hand_ring_link2"/>
    <exclude body1="xhand_left-left_hand_ring_link2" body2="xhand_left-left_hand_ringback_link2"/>
    <exclude body1="xhand_left-left_hand_ring_link2" body2="xhand_left-left_hand_ring_tip"/>
    <exclude body1="xhand_left" body2="xhand_left-left_hand_pinky_link1"/>
    <exclude body1="xhand_left-left_hand_pinky_link1" body2="xhand_left-left_hand_pinkyback_link1"/>
    <exclude body1="xhand_left-left_hand_pinky_link1" body2="xhand_left-left_hand_pinky_link2"/>
    <exclude body1="xhand_left-left_hand_pinky_link2" body2="xhand_left-left_hand_pinkyback_link2"/>
    <exclude body1="xhand_left-left_hand_pinky_link2" body2="xhand_left-left_hand_pinky_tip"/>
  </contact>
  <sensor>
    <framepos name="xhand_left-left_hand_link_site_pos" objtype="site" objname="xhand_left-left_hand_link_site"/>
    <framequat name="xhand_left-left_hand_link_site_quat" objtype="site" objname="xhand_left-left_hand_link_site"/>
    <framelinvel name="xhand_left-left_hand_link_site_linvel" objtype="site" objname="xhand_left-left_hand_link_site"/>
    <frameangvel name="xhand_left-left_hand_link_site_angvel" objtype="site" objname="xhand_left-left_hand_link_site"/>
    <velocimeter name="xhand_left-left_hand_link_site_vel" site="xhand_left-left_hand_link_site"/>
  </sensor>
  <equality>
    <weld body1="xhand_left" body2="xhand_left-left-wrist"/>
    <weld body1="xhand_left-left_hand_index_rota_tip" body2="xhand_left-left-index-finger-tip"/>
    <weld body1="xhand_left-left_hand_mid_tip" body2="xhand_left-left-middle-finger-tip"/>
    <weld body1="xhand_left-left_hand_ring_tip" body2="xhand_left-left-ring-finger-tip"/>
    <weld body1="xhand_left-left_hand_pinky_tip" body2="xhand_left-left-pinky-finger-tip"/>
    <weld body1="xhand_left-left_hand_thumb_rota_tip" body2="xhand_left-left-thumb-tip"/>
    /
  </equality>
</mujoco>